Workbook
Name CreativeShifts: Lists!$E$1:$E$7
Name Errors: Lists!$D$1
Name Omissions: Lists!$C$1:$C$2
Name Reproduction: Lists!$B$1:$B$4

Sheet Lists
A1: 1. Reproduction | B1: Retention | C1: Creative Omission | D1: Error | E1: Abstraction – Superordinate Term | G1: 1. Reproduction | H1: Reproduction
A2: 2. Omissions | B2: Specification | C2: Shortcut Solution | E2: Abstraction – Paraphrase | G2: 2. Omissions | H2: Omissions
A3: 3. Errors | B3: Direct Translation | E3: Concretisation – Addition | G3: 3. Errors | H3: Errors
A4: 4. Creative Shifts | B4: Official Translation | E4: Concretisation – Completion | G4: 4. Creative Shifts | H4: CreativeShifts
E5: Modification – Cultural
E6: Modification – Situational
E7: Modification – Historical

Sheet Dashboard
B1: EVALUATION DASHBOARD — Category Distribution (4 Models × 5 Prompts)
B3: ℹ Fill dropdowns in the Evaluation sheet — counts update here automatically.
B5: Model A - Translategemma
B6: Prompt | C6: Reproduction | D6: Omissions | E6: Errors | F6: Creative Shifts | G6: Total | H6: % Done
B7: Baseline | C7: =COUNTIF(Evaluation!I3:I202,"1. Reproduction") -> 82 | D7: =COUNTIF(Evaluation!I3:I202,"2. Omissions") -> 16 | E7: =COUNTIF(Evaluation!I3:I202,"3. Errors") -> 22 | F7: =COUNTIF(Evaluation!I3:I202,"4. Creative Shifts") -> 80 | G7: =COUNTIF(Evaluation!I3:I202,"<>") -> 200 | H7: =IFERROR(G7/200,"") -> 1
B8: Few-shot 1 | C8: =COUNTIF(Evaluation!O3:O202,"1. Reproduction") -> 101 | D8: =COUNTIF(Evaluation!O3:O202,"2. Omissions") -> 14 | E8: =COUNTIF(Evaluation!O3:O202,"3. Errors") -> 24 | F8: =COUNTIF(Evaluation!O3:O202,"4. Creative Shifts") -> 61 | G8: =COUNTIF(Evaluation!O3:O202,"<>") -> 200 | H8: =IFERROR(G8/200,"") -> 1
B9: Few-shot 2 | C9: =COUNTIF(Evaluation!U3:U202,"1. Reproduction") -> 112 | D9: =COUNTIF(Evaluation!U3:U202,"2. Omissions") -> 11 | E9: =COUNTIF(Evaluation!U3:U202,"3. Errors") -> 23 | F9: =COUNTIF(Evaluation!U3:U202,"4. Creative Shifts") -> 54 | G9: =COUNTIF(Evaluation!U3:U202,"<>") -> 200 | H9: =IFERROR(G9/200,"") -> 1
B10: CoT 1 | C10: =COUNTIF(Evaluation!AA3:AA202,"1. Reproduction") -> 83 | D10: =COUNTIF(Evaluation!AA3:AA202,"2. Omissions") -> 13 | E10: =COUNTIF(Evaluation!AA3:AA202,"3. Errors") -> 26 | F10: =COUNTIF(Evaluation!AA3:AA202,"4. Creative Shifts") -> 78 | G10: =COUNTIF(Evaluation!AA3:AA202,"<>") -> 200 | H10: =IFERROR(G10/200,"") -> 1
B11: CoT 2 | C11: =COUNTIF(Evaluation!AG3:AG202,"1. Reproduction") -> 82 | D11: =COUNTIF(Evaluation!AG3:AG202,"2. Omissions") -> 19 | E11: =COUNTIF(Evaluation!AG3:AG202,"3. Errors") -> 29 | F11: =COUNTIF(Evaluation!AG3:AG202,"4. Creative Shifts") -> 70 | G11: =COUNTIF(Evaluation!AG3:AG202,"<>") -> 200 | H11: =IFERROR(G11/200,"") -> 1
B14: Model B - Qwen
B15: Prompt | C15: Reproduction | D15: Omissions | E15: Errors | F15: Creative Shifts | G15: Total | H15: % Done
B16: Baseline | C16: =COUNTIF(Evaluation!AM3:AM202,"1. Reproduction") -> 149 | D16: =COUNTIF(Evaluation!AM3:AM202,"2. Omissions") -> 1 | E16: =COUNTIF(Evaluation!AM3:AM202,"3. Errors") -> 29 | F16: =COUNTIF(Evaluation!AM3:AM202,"4. Creative Shifts") -> 21 | G16: =COUNTIF(Evaluation!AM3:AM202,"<>") -> 200 | H16: =IFERROR(G16/200,"") -> 1
B17: Few-shot 1 | C17: =COUNTIF(Evaluation!AS3:AS202,"1. Reproduction") -> 161 | D17: =COUNTIF(Evaluation!AS3:AS202,"2. Omissions") -> 0 | E17: =COUNTIF(Evaluation!AS3:AS202,"3. Errors") -> 23 | F17: =COUNTIF(Evaluation!AS3:AS202,"4. Creative Shifts") -> 16 | G17: =COUNTIF(Evaluation!AS3:AS202,"<>") -> 200 | H17: =IFERROR(G17/200,"") -> 1
B18: Few-shot 2 | C18: =COUNTIF(Evaluation!AY3:AY202,"1. Reproduction") -> 161 | D18: =COUNTIF(Evaluation!AY3:AY202,"2. Omissions") -> 1 | E18: =COUNTIF(Evaluation!AY3:AY202,"3. Errors") -> 23 | F18: =COUNTIF(Evaluation!AY3:AY202,"4. Creative Shifts") -> 15 | G18: =COUNTIF(Evaluation!AY3:AY202,"<>") -> 200 | H18: =IFERROR(G18/200,"") -> 1
B19: CoT 1 | C19: =COUNTIF(Evaluation!BE3:BE202,"1. Reproduction") -> 160 | D19: =COUNTIF(Evaluation!BE3:BE202,"2. Omissions") -> 0 | E19: =COUNTIF(Evaluation!BE3:BE202,"3. Errors") -> 25 | F19: =COUNTIF(Evaluation!BE3:BE202,"4. Creative Shifts") -> 15 | G19: =COUNTIF(Evaluation!BE3:BE202,"<>") -> 200 | H19: =IFERROR(G19/200,"") -> 1
B20: CoT 2 | C20: =COUNTIF(Evaluation!BK3:BK202,"1. Reproduction") -> 150 | D20: =COUNTIF(Evaluation!BK3:BK202,"2. Omissions") -> 0 | E20: =COUNTIF(Evaluation!BK3:BK202,"3. Errors") -> 34 | F20: =COUNTIF(Evaluation!BK3:BK202,"4. Creative Shifts") -> 16 | G20: =COUNTIF(Evaluation!BK3:BK202,"<>") -> 200 | H20: =IFERROR(G20/200,"") -> 1
B23: Model C - Salamandra
B24: Prompt | C24: Reproduction | D24: Omissions | E24: Errors | F24: Creative Shifts | G24: Total | H24: % Done
B25: Baseline | C25: =COUNTIF(Evaluation!BQ3:BQ202,"1. Reproduction") -> 162 | D25: =COUNTIF(Evaluation!BQ3:BQ202,"2. Omissions") -> 2 | E25: =COUNTIF(Evaluation!BQ3:BQ202,"3. Errors") -> 12 | F25: =COUNTIF(Evaluation!BQ3:BQ202,"4. Creative Shifts") -> 24 | G25: =COUNTIF(Evaluation!BQ3:BQ202,"<>") -> 200 | H25: =IFERROR(G25/200,"") -> 1
B26: Few-shot 1 | C26: =COUNTIF(Evaluation!BW3:BW202,"1. Reproduction") -> 164 | D26: =COUNTIF(Evaluation!BW3:BW202,"2. Omissions") -> 2 | E26: =COUNTIF(Evaluation!BW3:BW202,"3. Errors") -> 14 | F26: =COUNTIF(Evaluation!BW3:BW202,"4. Creative Shifts") -> 20 | G26: =COUNTIF(Evaluation!BW3:BW202,"<>") -> 200 | H26: =IFERROR(G26/200,"") -> 1
B27: Few-shot 2 | C27: =COUNTIF(Evaluation!CC3:CC202,"1. Reproduction") -> 163 | D27: =COUNTIF(Evaluation!CC3:CC202,"2. Omissions") -> 1 | E27: =COUNTIF(Evaluation!CC3:CC202,"3. Errors") -> 17 | F27: =COUNTIF(Evaluation!CC3:CC202,"4. Creative Shifts") -> 19 | G27: =COUNTIF(Evaluation!CC3:CC202,"<>") -> 200 | H27: =IFERROR(G27/200,"") -> 1
B28: CoT 1 | C28: =COUNTIF(Evaluation!CI3:CI202,"1. Reproduction") -> 159 | D28: =COUNTIF(Evaluation!CI3:CI202,"2. Omissions") -> 3 | E28: =COUNTIF(Evaluation!CI3:CI202,"3. Errors") -> 15 | F28: =COUNTIF(Evaluation!CI3:CI202,"4. Creative Shifts") -> 23 | G28: =COUNTIF(Evaluation!CI3:CI202,"<>") -> 200 | H28: =IFERROR(G28/200,"") -> 1
B29: CoT 2 | C29: =COUNTIF(Evaluation!CO3:CO202,"1. Reproduction") -> 162 | D29: =COUNTIF(Evaluation!CO3:CO202,"2. Omissions") -> 1 | E29: =COUNTIF(Evaluation!CO3:CO202,"3. Errors") -> 17 | F29: =COUNTIF(Evaluation!CO3:CO202,"4. Creative Shifts") -> 20 | G29: =COUNTIF(Evaluation!CO3:CO202,"<>") -> 200 | H29: =IFERROR(G29/200,"") -> 1
B32: Model D
B33: Prompt | C33: Reproduction | D33: Omissions | E33: Errors | F33: Creative Shifts | G33: Total | H33: % Done
B34: Baseline | C34: =COUNTIF(Evaluation!#REF!,"1. Reproduction") -> #REF! | D34: =COUNTIF(Evaluation!#REF!,"2. Omissions") -> #REF! | E34: =COUNTIF(Evaluation!#REF!,"3. Errors") -> #REF! | F34: =COUNTIF(Evaluation!#REF!,"4. Creative Shifts") -> #REF! | G34: =COUNTIF(Evaluation!#REF!,"<>") -> #REF! | H34: =IFERROR(G34/200,"")
B35: Few-shot 1 | C35: =COUNTIF(Evaluation!#REF!,"1. Reproduction") -> #REF! | D35: =COUNTIF(Evaluation!#REF!,"2. Omissions") -> #REF! | E35: =COUNTIF(Evaluation!#REF!,"3. Errors") -> #REF! | F35: =COUNTIF(Evaluation!#REF!,"4. Creative Shifts") -> #REF! | G35: =COUNTIF(Evaluation!#REF!,"<>") -> #REF! | H35: =IFERROR(G35/200,"")
B36: Few-shot 2 | C36: =COUNTIF(Evaluation!#REF!,"1. Reproduction") -> #REF! | D36: =COUNTIF(Evaluation!#REF!,"2. Omissions") -> #REF! | E36: =COUNTIF(Evaluation!#REF!,"3. Errors") -> #REF! | F36: =COUNTIF(Evaluation!#REF!,"4. Creative Shifts") -> #REF! | G36: =COUNTIF(Evaluation!#REF!,"<>") -> #REF! | H36: =IFERROR(G36/200,"")
B37: CoT 1 | C37: =COUNTIF(Evaluation!#REF!,"1. Reproduction") -> #REF! | D37: =COUNTIF(Evaluation!#REF!,"2. Omissions") -> #REF! | E37: =COUNTIF(Evaluation!#REF!,"3. Errors") -> #REF! | F37: =COUNTIF(Evaluation!#REF!,"4. Creative Shifts") -> #REF! | G37: =COUNTIF(Evaluation!#REF!,"<>") -> #REF! | H37: =IFERROR(G37/200,"")
B38: CoT 2 | C38: =COUNTIF(Evaluation!#REF!,"1. Reproduction") -> #REF! | D38: =COUNTIF(Evaluation!#REF!,"2. Omissions") -> #REF! | E38: =COUNTIF(Evaluation!#REF!,"3. Errors") -> #REF! | F38: =COUNTIF(Evaluation!#REF!,"4. Creative Shifts") -> #REF! | G38: =COUNTIF(Evaluation!#REF!,"<>") -> #REF! | H38: =IFERROR(G38/200,"")

Sheet Evaluation
H1: Model A - TranslateGemma | AL1: Model B - Qwen | BP1: Model C - Salamandra
A2: text_previous | B2: text_analyzed | C2: text_after | D2: text_analyzed | E2: macrocategory | F2: subcategory_num | G2: subcategory | H2: translation_translategemma_baseline | I2: Baseline ▼ Category | J2: Baseline ▼ Subcategory | K2: Mantains informal register? | L2: Intensity of informality | M2: Baseline Comments | N2: translation_translategemma_fewshot1 | O2: Few-shot 1 ▼ Category | P2: Few-shot 1 ▼ Subcategory | Q2: Mantains informal register? | R2: Intensity of informality | S2: Few-shot 1 Comments | T2: translation_translategemma_fewshot2 | U2: Few-shot 2 ▼ Category | V2: Few-shot 2 ▼ Subcategory | W2: Mantains informal register? | X2: Intensity of informality | Y2: Few-shot 2 Comments | Z2: translation_translategemma_CoT1 | AA2: CoT 1 ▼ Category | AB2: CoT 1 ▼ Subcategory | AC2: Mantains informal register? | AD2: Intensity of informality | AE2: CoT 1 Comments | AF2: translation_translategemma_CoT2 | AG2: CoT 2 ▼ Category | AH2: CoT 2 ▼ Subcategory | AI2: Mantains informal register? | AJ2: Intensity of informality | AK2: CoT 2 Comments | AL2: translation_qwen_baseline | AM2: Baseline ▼ Category | AN2: Baseline ▼ Subcategory | AO2: Mantains informal register? | AP2: Intensity of informality | AQ2: Baseline Comments | AR2: translation_qwen_fewshot1 | AS2: Few-shot 1 ▼ Category | AT2: Few-shot 1 ▼ Subcategory | AU2: Mantains informal register? | AV2: Intensity of informality | AW2: Few-shot 1 Comments | AX2: translation_qwen_fewshot2 | AY2: Few-shot 2 ▼ Category | AZ2: Few-shot 2 ▼ Subcategory | BA2: Mantains informal register? | BB2: Intensity of informality | BC2: Few-shot 2 Comments | BD2: translation_qwen_CoT1 | BE2: CoT 1 ▼ Category | BF2: CoT 1 ▼ Subcategory | BG2: Mantains informal register? | BH2: Intensity of informality | BI2: CoT 1 Comments | BJ2: translation_qwen_CoT2 | BK2: CoT 2 ▼ Category | BL2: CoT 2 ▼ Subcategory | BM2: Mantains informal register? | BN2: Intensity of informality | BO2: CoT 2 Comments | BP2: translation_salam_baseline | BQ2: Baseline ▼ Category | BR2: Baseline ▼ Subcategory | BS2: Mantains informal register? | BT2: Intensity of informality | BU2: Baseline Comments | BV2: translation_salam_fewshot1 | BW2: Few-shot 1 ▼ Category | BX2: Few-shot 1 ▼ Subcategory | BY2: Mantains informal register? | BZ2: Intensity of informality | CA2: Few-shot 1 Comments | CB2: translation_salam_fewshot2 | CC2: Few-shot 2 ▼ Category | CD2: Few-shot 2 ▼ Subcategory | CE2: Mantains informal register? | CF2: Intensity of informality | CG2: Few-shot 2 Comments | CH2: translation_salam_CoT1 | CI2: CoT 1 ▼ Category | CJ2: CoT 1 ▼ Subcategory | CK2: Mantains informal register? | CL2: Intensity of informality | CM2: CoT 1 Comments | CN2: translation_salam_CoT2 | CO2: CoT 2 ▼ Category | CP2: CoT 2 ▼ Subcategory | CQ2: Mantains informal register? | CR2: Intensity of informality | CS2: CoT 2 Comments
A3: [empieza tema de conversación] | B3: O sigui, jo hi ha gent també i de vegades ja penso, hòstia, gordi, i si calles la putíssima boca. En plan, ostres, nano, per què no calles, loca? | C3: És que també té moltes parts negatives d'això i té una cosa, en plan, jo tampoc considero que sigui superpolèmica, en plan, jo, per exemple, soc molt cordial, no em mullo, així com tu sí que sento que dius opinions com molt polèmiques, jo amb això, gens. | D3: O sigui, jo hi ha gent també i de vegades ja penso, hòstia, gordi, i si calles la putíssima boca. En plan, ostres, nano, per què no calles, loca? | E3: 3. Pragmatics and Discourse | F3: 3.2 | G3: Familiar address or vocatives | H3: Mira, a veces hay gente que me saca de quicio, y pienso, "¡hostia!, ¡qué pesado!, ¿por qué no te callas?". En serio, a veces pienso, "chico/chica, ¿por qué no te puedes quedar callado/a?". | I3: 4. Creative Shifts | J3: Abstraction – Superordinate Term | K3: NO | N3: O sea, hay gente que también opina así, y a veces pienso, joder, ¿y si callaras de una vez? En plan, oye, ¿por qué no te callas, loca? | O3: 2. Omissions | P3: Shortcut Solution | Q3: NO | T3: O sea, también hay gente que opina, y a veces pienso, ¡hostia, si pudieras callarte la boca! O sea, ¿pero por qué no te callas, loca? | U3: 2. Omissions | V3: Shortcut Solution | W3: NO | Z3: O sea, hay gente que también opina así, y a veces pienso, ¡madre mía!, ¿por qué no te callas de una vez? En plan, ¡ostras!, ¿por qué no te callas, loca? | AA3: 2. Omissions | AB3: Shortcut Solution | AC3: NO | AF3: O sea, hay gente que también opina así, y a veces pienso, ¡madre mía!, ¿por qué no te callas de una vez? En plan, ¿pero qué dices, tonto? ¿Por qué no te callas, loca? | AG3: 2. Omissions | AH3: Shortcut Solution | AI3: NO | AL3: O sigui, hay gente también, y a veces ya pienso, joder, gordo, y si callaras la puta boca. En plan, mierda, chaval, ¿por qué no callas, loca? | AM3: 4. Creative Shifts | AN3: Abstraction – Superordinate Term | AO3: YES | AP3: LESS | AR3: O sea, hay gente también y a veces ya pienso, hóstia, gordo, y si callas la puta boca. En plan, ostras, nano, por qué no callas, loca? | AS3: 1. Reproduction | AT3: Direct Translation | AU3: YES | AV3: SAME | AX3: O sea, yo también hay gente y de vez en cuando ya pienso, joder, gordo, y si callas la puta boca. En plan, mierda, tío, por qué no callas, loca? | AY3: 4. Creative Shifts | AZ3: Modification – Cultural | BA3: YES | BB3: LESS | BD3: O sea, yo también hay gente, y a veces ya pienso, joder, gordo, y si callaras la puta boca. En plan, mierda, tío, ¿por qué no callas, loca? | BE3: 4. Creative Shifts | BF3: Modification – Cultural | BG3: YES | BH3: LESS | BJ3: Bueno, también hay gente, y a veces ya pienso, mierda, gordo, y si callaras la puta boca. En plan, joder, tío, ¿por qué no te callas, loca? | BK3: 4. Creative Shifts | BL3: Modification – Cultural | BM3: YES | BN3: LESS | BP3: O sea, yo también hay gente y a veces ya pienso, hostia, gordi, y si callas la puta boca. En plan, ¡ostras, tío, por qué no callas, loca? | BQ3: 4. Creative Shifts | BR3: Modification – Cultural | BS3: YES | BT3: LESS | BV3: O sea, yo también hay gente y a veces ya pienso, hostia, gordi, y si callas la puta boca. En plan, joder, tío, por qué no callas, loca? | BW3: 4. Creative Shifts | BX3: Modification – Cultural | BY3: YES | BZ3: LESS | CB3: O sea, yo también hay gente y a veces ya pienso, hostia, gordi, y si callas la puta boca. En plan, joder, tío, por qué no callas, loca? | CC3: 4. Creative Shifts | CD3: Modification – Cultural | CE3: YES | CF3: LESS | CH3: O sea, yo también hay gente y a veces ya pienso, hostia, gordi, y si callas la puta boca. En plan, ¡ostras, tío, por qué no callas, loca? | CI3: 4. Creative Shifts | CJ3: Modification – Cultural | CK3: YES | CL3: LESS | CN3: O sea, yo hay gente también y a veces ya pienso, hostia, gordi, y si callas la putísima boca. En plan, ostras, nano, ¿por qué no callas, loca? | CO3: 1. Reproduction | CP3: Direct Translation | CQ3: YES | CR3: SAME
A4: [empieza tema de conversación] | B4: A tot això, a tu realment te la suda molt el que pensi la resta? És que no ho sé, perquè jo et diria que no, que no m'importa gens el que pensi la resta, i de fet crec que és una cosa que m'ha caracteritzat des de sempre, i en èpoques molt difícils com l'adolescència, etcètera, jo també m'he mantingut molt ferma amb qui soc jo | C4: Sempre he fet una mica el que m'ha vingut de gust, encara que fos una bogeria, però després penso que és mentida, que segur que penso tot el rato en realitat, perquè al final és que vivim en societat, és que si realment no penses en els altres, llavors ets un d'aquests bojos que va descalços i despullat i cridant pel carrer. | D4: A tot això, a tu realment te la suda molt el que pensi la resta? És que no ho sé, perquè jo et diria que no, que no m'importa gens el que pensi la resta, i de fet crec que és una cosa que m'ha caracteritzat des de sempre, i en èpoques molt difícils com l'adolescència, etcètera, jo també m'he mantingut molt ferma amb qui soc jo | E4: 1. Lexicon and Vocabulary | F4: 1.2 | G4: Colloquial lexicon and slang | H4: En todo esto, ¿a ti realmente te importa mucho lo que piense el resto? Es que no lo sé, porque yo te diría que no, que no me importa en absoluto lo que piense la gente, y de hecho creo que es algo que me ha caracterizado siempre, y en épocas muy difíciles como la adolescencia, etc., yo también me he mantenido muy firme con lo que soy. | I4: 4. Creative Shifts | J4: Abstraction – Paraphrase | K4: NO | N4: "Dicho esto, ¿a ti realmente te importa mucho lo que piense el resto? Es que no lo sé, porque yo te diría que no, que no me importa nada lo que piense la gente, y de hecho creo que es algo que me ha caracterizado siempre, y en épocas muy difíciles como la adolescencia, etcétera, yo también me he mantenido muy firme con quien soy." | O4: 4. Creative Shifts | P4: Abstraction – Paraphrase | Q4: NO | T4: A todo esto, ¿a ti realmente te importa mucho lo que piense el resto? Es que no lo sé, porque yo te diría que no, que no me importa nada lo que piense el resto, y de hecho creo que es algo que me ha caracterizado desde siempre, y en épocas muy difíciles como la adolescencia, etc., yo también me he mantenido muy firme con quien soy. | U4: 4. Creative Shifts | V4: Abstraction – Paraphrase | W4: NO | Z4: De todo esto, ¿a ti realmente te importa mucho lo que piense el resto? Es que no lo sé, porque yo te diría que no, que no me importa en absoluto lo que piense la gente, y de hecho, creo que es algo que me ha caracterizado siempre, y en épocas muy difíciles como la adolescencia, etcétera, yo también me he mantenido muy firme con lo que soy. | AA4: 4. Creative Shifts | AB4: Abstraction – Paraphrase | AC4: NO | AF4: A todo esto, ¿realmente te da igual lo que piense el resto? Es que no lo sé, porque yo te diría que no, que no me importa en absoluto lo que piense la gente, y de hecho creo que es algo que me ha caracterizado siempre, y en épocas muy difíciles como la adolescencia, etcétera, yo también me he mantenido muy firme con quien soy. | AG4: 4. Creative Shifts | AH4: Abstraction – Paraphrase | AI4: NO | AL4: A todo esto, ¿a ti realmente te importa mucho lo que piensen los demás? Es que no lo sé, porque yo te diría que no, que no me importa nada lo que piensen los demás, y de hecho creo que es algo que me ha caracterizado siempre, y en épocas muy difíciles como la adolescencia, etcétera, yo también me he mantenido muy firme con quién soy. | AM4: 4. Creative Shifts | AN4: Abstraction – Paraphrase | AO4: NO | AR4: A todo esto, a ti realmente te importa mucho lo que piense el resto? Es que no lo sé, porque yo te diría que no, que no me importa nada lo que piense el resto, y de hecho creo que es algo que me ha caracterizado siempre, y en épocas muy difíciles como la adolescencia, etcétera, yo también me he mantenido muy firme con quién soy. | AS4: 4. Creative Shifts | AT4: Abstraction – Paraphrase | AU4: NO | AX4: A todo esto, a ti realmente te importa mucho lo que piense el resto? Es que no lo sé, porque yo te diría que no, que no me importa nada lo que piense el resto, y de hecho creo que es algo que me ha caracterizado siempre, y en épocas muy difíciles como la adolescencia, etcétera, yo también me he mantenido muy firme con quién soy. | AY4: 4. Creative Shifts | AZ4: Abstraction – Paraphrase | BA4: NO | BD4: A todo esto, ¿a ti realmente te importa mucho lo que piense el resto? Es que no lo sé, porque yo te diría que no, que no me importa nada lo que piense el resto, y de hecho creo que es algo que me ha caracterizado siempre, y en épocas muy difíciles como la adolescencia, etcétera, yo también me he mantenido muy firme con quién soy. | BE4: 4. Creative Shifts | BF4: Abstraction – Paraphrase | BG4: NO | BJ4: A todo esto, ¿a ti realmente te importa mucho lo que piensen los demás? La verdad es que no lo sé, porque yo te diría que no, que no me importa nada lo que piensen los demás, y de hecho creo que es algo que me ha caracterizado siempre, y en épocas muy difíciles como la adolescencia, etcétera, también he estado muy firme con respecto a quién soy yo. | BK4: 4. Creative Shifts | BL4: Abstraction – Paraphrase | BM4: NO | BP4: A todo esto, ¿a ti realmente te la suda mucho lo que piensen los demás? Porque yo te diría que no, que no me importa nada lo que piensen los demás, y de hecho creo que es algo que me ha caracterizado desde siempre, y en épocas muy difíciles como la adolescencia, etcétera, yo también me he mantenido muy firme con quien soy | BQ4: 1. Reproduction | BR4: Direct Translation | BS4: YES | BT4: SAME | BV4: A todo esto, ¿a ti realmente te la suda mucho lo que piense el resto? Es que no sé, porque yo te diría que no, que no me importa nada lo que piense el resto, y de hecho creo que es algo que me ha caracterizado desde siempre, y en épocas muy difíciles como la adolescencia, etcétera, yo también me he mantenido muy firme con quien soy yo | BW4: 1. Reproduction | BX4: Direct Translation | BY4: YES | BZ4: SAME | CB4: A todo esto, ¿a ti realmente te la suda mucho lo que piense el resto? Es que no sé, porque yo te diría que no, que no me importa nada lo que piense el resto, y de hecho creo que es algo que me ha caracterizado desde siempre, y en épocas muy difíciles como la adolescencia, etcétera, yo también me he mantenido muy firme con quien soy yo | CC4: 1. Reproduction | CD4: Direct Translation | CE4: YES | CF4: SAME | CH4: A todo esto, ¿a ti realmente te la suda mucho lo que piensen los demás? Porque yo te diría que no, que no me importa nada lo que piensen los demás, y de hecho creo que es algo que me ha caracterizado desde siempre, y en épocas muy difíciles como la adolescencia, etcétera, yo también me he mantenido muy firme con quien soy Siempre he hecho un poco lo que me ha venido en gana, aunque fuera una locura, pero luego pienso que es mentira, que seguro que pienso todo el rato en realidad, porque al final es que vivimos en sociedad, es que si realmente no piensas en los demás, entonces eres uno de esos locos que va descalzo y desnudo gritando por la calle. | CI4: 1. Reproduction | CJ4: Direct Translation | CK4: YES | CL4: SAME | CN4: A todo esto, ¿a ti realmente te la suda mucho lo que piensen los demás? Es que no sé, porque yo te diría que no, que no me importa nada lo que piensen los demás, y de hecho creo que es algo que me ha caracterizado desde siempre, y en épocas muy difíciles como la adolescencia, etcétera, yo también me he mantenido muy firme con quien soy. | CO4: 1. Reproduction | CP4: Direct Translation | CQ4: YES | CR4: SAME
A5: [empieza tema de conversación] | B5: Jo sóc molt desconfiada, però molt desconfiada. Jo pense que te me l'estan a punt de fotre per l'esquena. Tot el rato. | C5: Mira, per exemple, el Marc Andreu, jo encara no critico amb ell per WhatsApp, hem de quedar presencialment per criticar, perquè no vull que quedi constància la meva criticada. Imagina la desconfiada que soc. | D5: Jo sóc molt desconfiada, però molt desconfiada. Jo pense que te me l'estan a punt de fotre per l'esquena. Tot el rato. | E5: 1. Lexicon and Vocabulary | F5: 1.2 | G5: Colloquial lexicon and slang | H5: Soy muy desconfiada, pero muchísimo. Creo que me están a punto de apuñalar por la espalda. Todo el rato. | I5: 4. Creative Shifts | J5: Modification – Situational | K5: YES | L5: LESS | N5: Soy muy desconfiada, la verdad. Creo que me están preparando una jugada por la espalda. Todo el rato. | O5: 4. Creative Shifts | P5: Modification – Situational | Q5: YES | R5: LESS | T5: Yo soy muy desconfiada, pero muchísimo. Yo pienso que te están a punto de clavar una puñalada por la espalda. Todo el rato. | U5: 4. Creative Shifts | V5: Modification – Situational | W5: YES | X5: SAME | Z5: Soy muy desconfiada, la verdad. Creo que me están tendiendo una trampa constantemente. | AA5: 4. Creative Shifts | AB5: Abstraction – Paraphrase | AC5: NO | AF5: Yo soy muy desconfiada, pero muchísimo. Yo pienso que me están intentando engañar a mis espaldas. Todo el rato. | AG5: 4. Creative Shifts | AH5: Abstraction – Paraphrase | AI5: NO | AL5: Estoy muy desconfiada, pero muy desconfiada. Creo que me van a pillar por la espalda. Todo el rato. | AM5: 4. Creative Shifts | AN5: Modification – Situational | AO5: NO | AR5: Yo soy muy desconfiada, pero muy desconfiada. Yo pienso que me van a hacer una trampa por la espalda. Todo el rato. | AS5: 4. Creative Shifts | AT5: Abstraction – Paraphrase | AU5: NO | AX5: Yo soy muy desconfiada, pero muy desconfiada. Yo pienso que te me lo están a punto de liar por la espalda. Todo el rato. | AY5: 4. Creative Shifts | AZ5: Modification – Situational | BA5: YES | BB5: LESS | BD5: Yo soy muy desconfiada, pero muy desconfiada. Yo pienso que te me lo están a punto de liar por la espalda. Todo el rato. | BE5: 4. Creative Shifts | BF5: Modification – Situational | BG5: YES | BH5: LESS | BJ5: Soy muy desconfiada, pero muy desconfiada. Creo que me están a punto de liar por la espalda todo el rato. | BK5: 4. Creative Shifts | BL5: Modification – Situational | BM5: YES | BN5: LESS | BP5: Yo soy muy desconfiada, pero muy desconfiada. Yo pienso que te la están a punto de meter por la espalda todo el rato. | BQ5: 4. Creative Shifts | BR5: Modification – Situational | BS5: YES | BT5: LESS | BV5: Yo soy muy desconfiada, pero muy desconfiada. Yo pienso que te me la están a punto de meter por la espalda. Todo el rato. | BW5: 4. Creative Shifts | BX5: Modification – Situational | BY5: YES | BZ5: LESS | CB5: Yo soy muy desconfiada, pero muy desconfiada. Yo pienso que te me la están a punto de meter por la espalda. Todo el rato. | CC5: 4. Creative Shifts | CD5: Modification – Situational | CE5: YES | CF5: LESS | CH5: Yo soy muy desconfiada, pero muy desconfiada. Yo pienso que te la están a punto de meter por la espalda. Todo el rato. | CI5: 4. Creative Shifts | CJ5: Modification – Situational | CK5: YES | CL5: LESS | CN5: Yo soy muy desconfiada, pero muy desconfiada. Yo pienso que te la están a punto de meter por la espalda. Todo el rato. | CO5: 4. Creative Shifts | CP5: Modification – Situational | CQ5: YES | CR5: LESS
A6: [empieza tema de conversación] | B6: O sigui, és que realment me vaig començar a fer coneguda perquè ho vaig deixar amb la meva parella i em vaig tornar loca. En plan, uau, he perdut O sigui, clar, és que jo en aquell moment se m'acabava el puto món, t'ho juro. I ara ho veig en perspectiva i dic, amor, relaxat. | C6: Però és normal, és que hi ha moment quan ho deixes Hi ha gent que diu, és que em torno boja. O sigui, una ruptura sempre és un moment de loca. | D6: O sigui, és que realment me vaig començar a fer coneguda perquè ho vaig deixar amb la meva parella i em vaig tornar loca. En plan, uau, he perdut O sigui, clar, és que jo en aquell moment se m'acabava el puto món, t'ho juro. I ara ho veig en perspectiva i dic, amor, relaxat. | E6: 4. Register and Tone | F6: 4.1 | G6: Hyperbole and exaggeration | H6: O sea, la verdad es que empecé a darme a conocer cuando rompí con mi pareja y me volví loca. En plan, ¡uf!, lo perdí todo. O sea, claro, en ese momento, mi mundo se estaba viniendo abajo, te lo juro. Y ahora lo veo con perspectiva y digo, cariño, relájate. | I6: 4. Creative Shifts | J6: Abstraction – Paraphrase | K6: NO | N6: O sea, es que realmente empecé a darme a conocer porque rompí con mi pareja y me volví loca. En plan, ¡guau!, me vino todo encima. O sea, claro, es que yo en ese momento se me acababa el mundo, te lo juro. Y ahora lo veo con perspectiva y digo, "amor, relájate". | O6: 4. Creative Shifts | P6: Abstraction – Paraphrase | Q6: NO | T6: O sea, es que realmente empecé a darme a conocer porque rompí con mi pareja y me volví loca. En plan, vaya, me perdí... O sea, claro, es que en ese momento se me acababa el mundo, te lo juro. Y ahora lo veo en perspectiva y digo, amor, relájate. | U6: 4. Creative Shifts | V6: Abstraction – Paraphrase | W6: NO | Z6: O sea, en realidad empecé a darme a conocer cuando rompí con mi pareja y me volví loca. En plan, ¡guau!, me vino el mundo encima. O sea, claro, en ese momento, te juro, mi vida se estaba desmoronando. Y ahora lo veo con perspectiva y digo, cariño, relájate. | AA6: 4. Creative Shifts | AB6: Abstraction – Paraphrase | AC6: NO | AF6: O sea, en realidad empecé a darme a conocer porque rompí con mi pareja y me volví loca. En plan, ¡guau!, lo perdí todo. O sea, claro, en ese momento, mi mundo se estaba desmoronando, te lo juro. Y ahora lo veo con perspectiva y digo, "tranquilo, todo va a estar bien". | AG6: 4. Creative Shifts | AH6: Abstraction – Paraphrase | AI6: NO | AL6: O sigui, es que realmente me empecé a hacer famosa porque dejé a mi pareja y me volví loca. En plan, uau, perdí el culo, ¿sabes? O sea, claro, en ese momento me acababa el mundo, te lo juro. Y ahora lo veo en perspectiva y digo, amor, relájate. | AM6: 4. Creative Shifts | AN6: Abstraction – Superordinate Term | AO6: NO | AR6: O sea, es que realmente me empecé a hacer famosa porque lo dejé con mi pareja y me volví loca. En plan, uau, he perdido, o sea, claro, es que en aquel momento se me acababa el puto mundo, te lo juro. Y ahora lo veo en perspectiva y digo, amor, relájate. | AS6: 1. Reproduction | AT6: Direct Translation | AU6: YES | AV6: SAME | AX6: O sea, es que realmente me empecé a hacer conocida porque lo dejé con mi pareja y me volví loca. En plan, uau, he perdido O sea, claro, es que en ese momento se me acababa el puto mundo, te lo juro. Y ahora lo veo en perspectiva y digo, amor, relájate. | AY6: 1. Reproduction | AZ6: Direct Translation | BA6: YES | BB6: SAME | BD6: O sea, es que realmente me empecé a hacer conocida porque lo dejé con mi pareja y me volví loca. En plan, uau, he perdido O sea, claro, es que en ese momento se me acababa el puto mundo, te lo juro. Y ahora lo veo en perspectiva y digo, amor, relájate. | BE6: 1. Reproduction | BF6: Direct Translation | BG6: YES | BH6: SAME | BJ6: O sea, es que realmente me empecé a hacer famosa porque lo dejé con mi pareja y me volví loca. En plan, uau, he perdido, o sea, claro, es que en ese momento se me acababa el puto mundo, te lo juro. Y ahora lo veo en perspectiva y digo, amor, relájate. | BK6: 1. Reproduction | BL6: Direct Translation | BM6: YES | BN6: SAME | BP6: O sea, es que realmente me hice conocida porque lo dejé con mi pareja y me volví loca. En plan, uau, he perdido O sea, claro, es que yo en ese momento se me acababa el puto mundo, te lo juro. Y ahora lo veo en perspectiva y digo, amor, relájate. | BQ6: 1. Reproduction | BR6: Direct Translation | BS6: YES | BT6: SAME | BV6: O sea, es que realmente me hice conocida porque lo dejé con mi pareja y me volví loca. En plan, uau, he perdido O sea, claro, es que yo en ese momento se me acababa el puto mundo, te lo juro. Y ahora lo veo en perspectiva y digo, amor, relájate. | BW6: 1. Reproduction | BX6: Direct Translation | BY6: YES | BZ6: SAME | CB6: O sea, es que realmente me hice conocida porque lo dejé con mi pareja y me volví loca. En plan, uau, he perdido O sea, claro, es que yo en ese momento se me acababa el puto mundo, te lo juro. Y ahora lo veo en perspectiva y digo, amor, relájate. | CC6: 1. Reproduction | CD6: Direct Translation | CE6: YES | CF6: SAME | CH6: O sea, que realmente me hice conocida porque dejé a mi pareja y me volví loca. En plan, wow, he perdido O sea, claro, es que yo en ese momento se me acababa el puto mundo, te lo juro. Y ahora lo veo en perspectiva y digo, amor, relájate. | CI6: 1. Reproduction | CJ6: Direct Translation | CK6: YES | CL6: SAME | CN6: O sea, es que realmente me hice conocida porque lo dejé con mi pareja y me volví loca. En plan, uau, he perdido O sea, claro, es que yo en ese momento se me acababa el puto mundo, te lo juro. Y ahora lo veo en perspectiva y digo, amor, relájate. | CO6: 1. Reproduction | CP6: Direct Translation | CQ6: YES | CR6: SAME
A7: [empieza tema de conversación] | B7: És que, de fet, aquest és el primer meló que volia obrir de la solteria, que, clar, sembla que quan ets un home i estàs solter, és una solteria escollida, en plan, estic solter perquè vull, i si ets un lligón, a sobre ets el puto amo, però quan ets una noia i estàs soltera, ja és perquè ningú et vol, mai és soltera per voluntat pròpia, sempre la idea és estar soltera perquè algú té alguna tara i no la volen, i si a sobre ets una lligona, estàs desesperada. | C7: Llavors, clar, és que són 2 maneres de viure la solteria super diferent. | D7: És que, de fet, aquest és el primer meló que volia obrir de la solteria, que, clar, sembla que quan ets un home i estàs solter, és una solteria escollida, en plan, estic solter perquè vull, i si ets un lligón, a sobre ets el puto amo, però quan ets una noia i estàs soltera, ja és perquè ningú et vol, mai és soltera per voluntat pròpia, sempre la idea és estar soltera perquè algú té alguna tara i no la volen, i si a sobre ets una lligona, estàs desesperada. | E7: 1. Lexicon and Vocabulary | F7: 1.4 | G7: Idiomatic expressions and colloquial phraseology | H7: Es que, de hecho, este es el primer tema que quería tratar sobre la soltería, y claro, parece que cuando eres hombre y estás soltero, es una soltería elegida, o sea, estoy soltero porque quiero, y si eres atractivo, aún más, eres el dueño de tu vida. Pero cuando eres mujer y estás soltera, ya es porque nadie la quiere, nunca es soltera por propia voluntad, siempre la idea es que está soltera porque alguien tiene algún problema y no la quiere, y si encima eres atractiva, estás desesperada. | I7: 4. Creative Shifts | J7: Abstraction – Paraphrase | K7: NO | N7: Pues, de hecho, este es el primer tema que quería tratar sobre la soltería, que, claro, parece que cuando eres hombre y estás soltero, es una soltería elegida, como que estoy soltero porque quiero, y si además eres atractivo, eres el puto amo, pero cuando eres mujer y estás soltera, ya es porque nadie te quiere, nunca es soltería por voluntad propia, siempre la idea es estar soltera porque alguien tiene algún problema y no te quiere, y si además eres atractiva, estás desesperada. | O7: 4. Creative Shifts | P7: Abstraction – Paraphrase | Q7: NO | T7: Pues, de hecho, este es el primer melón que quería abrir sobre la soltería, que, claro, parece que cuando eres hombre y estás soltero, es una soltería elegida, vamos, estoy soltero porque quiero, y si eres un "ligón", encima eres el puto amo, pero cuando eres una chica y estás soltera, ya es porque nadie la quiere, nunca es soltera por voluntad propia, siempre la idea es estar soltera porque alguien tiene alguna tara y no la quieren, y si encima eres una "ligona", estás desesperada. | U7: 1. Reproduction | V7: Direct Translation | W7: YES | X7: SAME | Z7: Es que, de hecho, este es el primer tema que quería tratar sobre la soltería, y claro, parece que cuando eres hombre y estás soltero, es una soltería elegida, en plan, estoy soltero porque quiero, y si eres atractivo, encima eres el dueño de ti mismo, pero cuando eres mujer y estás soltera, ya es porque nadie te quiere, nunca es soltería por voluntad propia, siempre la idea es estar soltera porque alguien tiene algún problema y no la quiere, y si encima eres atractiva, estás desesperada. | AA7: 4. Creative Shifts | AB7: Abstraction – Paraphrase | AC7: NO | AF7: En realidad, este es el primer tema que quería abordar sobre la soltería, y es que, claro, parece que cuando eres hombre y estás soltero, es una soltería elegida, es decir, estás soltero porque quieres, y si eres atractivo, encima eres el dueño de tu vida. Pero cuando eres mujer y estás soltera, ya es porque nadie te quiere, nunca es soltería por voluntad propia, siempre la idea es que estás soltera porque alguien tiene algún problema y no te quiere, y si encima eres atractiva, estás desesperada. | AG7: 4. Creative Shifts | AH7: Abstraction – Paraphrase | AI7: NO | AL7: Pues, de hecho, este es el primer melo que quería abrir sobre la soltería, que, claro, parece que cuando eres un hombre y estás soltero, es una soltería elegida, en plan, estoy soltero porque quiero, y si además eres un ligue, encima eres el puto amo. Pero cuando eres una chica y estás soltera, ya es porque nadie te quiere, nunca es soltera por voluntad propia, siempre la idea es estar soltera porque alguien tiene alguna tara y no la quiere, y si encima eres una ligueona, estás desesperada. | AM7: 3. Errors | AO7: NO | AR7: Pues, de hecho, este es el primer meló que quería abrir de la soltería, que, claro, parece que cuando eres un hombre y estás soltero, es una soltería elegida, en plan, estoy soltero porque quiero, y si eres un ligue, a más es el puto amo, pero cuando eres una chica y estás soltera, ya es porque nadie te quiere, nunca es soltera por voluntad propia, siempre la idea es estar soltera porque alguien tiene alguna tara y no la quiere, y si a más eres una ligueona, estás desesperada. | AS7: 3. Errors | AU7: NO | AX7: Es que, de hecho, este es el primer melo que quería abrir de la soltería, que, claro, parece que cuando eres un hombre y estás soltero, es una soltería elegida, en plan, estoy soltero porque quiero, y si eres un ligón, a más, eres el puto amo, pero cuando eres una chica y estás soltera, ya es porque nadie te quiere, nunca es soltera por voluntad propia, siempre la idea es estar soltera porque alguien tiene alguna tara y no la quieren, y si a más eres una ligona, estás desesperada. | AY7: 3. Errors | BA7: NO | BD7: Claro, de hecho, este es el primer melo que quería abrir sobre la soltería, que, claro, parece que cuando eres un hombre y estás soltero, es una soltería elegida, en plan, estoy soltero porque quiero, y si eres un ligue, a más, eres el puto amo, pero cuando eres una chica y estás soltera, ya es porque nadie te quiere, nunca es soltera por voluntad propia, siempre la idea es estar soltera porque alguien tiene alguna tara y no la quiere, y si a más eres una ligueona, estás desesperada. | BE7: 3. Errors | BG7: NO | BJ7: Es que, de hecho, este es el primer melo que quería abrir de la soltería, que, claro, parece que cuando eres un hombre y estás soltero, es una soltería elegida, en plan, estoy soltero porque quiero, y si eres un ligón, a más, eres el puto amo, pero cuando eres una chica y estás soltera, ya es porque nadie te quiere, nunca es soltera por voluntad propia, siempre la idea es estar soltera porque alguien tiene alguna tara y no la quiere, y si a más eres una ligona, estás desesperada. | BK7: 3. Errors | BM7: NO | BP7: Es que, de hecho, este es el primer melón que quería abrir de la soltería, que, claro, parece que cuando eres un hombre y estás soltero, es una soltería elegida, en plan, estoy soltero porque quiero, y si eres un ligón, encima eres el puto amo, pero cuando eres una chica y estás soltera, ya es porque nadie te quiere, nunca es soltera por voluntad propia, siempre la idea es estar soltera porque alguien tiene algún defecto y no la quieren, y si encima eres una ligona, estás desesperada. | BQ7: 1. Reproduction | BR7: Direct Translation | BS7: YES | BT7: SAME | BV7: Es que, de hecho, este es el primer melón que quería abrir de la soltería, que, claro, parece que cuando eres un hombre y estás soltero, es una soltería elegida, en plan, estoy soltero porque quiero, y si eres un ligón, a sobre eres el puto amo, pero cuando eres una chica y estás soltera, ya es porque nadie te quiere, nunca es soltera por voluntad propia, siempre la idea es estar soltera porque alguien tiene algún defecto y no la quieren, y si encima eres una ligona, estás desesperada. | BW7: 1. Reproduction | BX7: Direct Translation | BY7: YES | BZ7: SAME | CB7: Es que, de hecho, este es el primer melón que quería abrir de la soltería, que, claro, parece que cuando eres un hombre y estás soltero, es una soltería elegida, en plan, estoy soltero porque quiero, y si eres un ligón, a sobre eres el puto amo, pero cuando eres una chica y estás soltera, ya es porque nadie te quiere, nunca es soltera por voluntad propia, siempre la idea es estar soltera porque alguien tiene algún defecto y no la quieren, y si encima eres una ligona, estás desesperada. | CC7: 1. Reproduction | CD7: Direct Translation | CE7: YES | CF7: SAME | CH7: Es que, de hecho, este es el primer melón que quería abrir de la soltería, que, claro, parece que cuando eres un hombre y estás soltero, es una soltería elegida, en plan, estoy soltero porque quiero, y si eres un ligón, encima eres el puto amo, pero cuando eres una chica y estás soltera, ya es porque nadie te quiere, nunca es soltera por voluntad propia, siempre la idea es estar soltera porque alguien tiene algún defecto y no la quieren, y si encima eres una ligona, estás desesperada. | CI7: 1. Reproduction | CJ7: Direct Translation | CK7: YES | CL7: SAME | CN7: Es que, de hecho, este es el primer melón que quería abrir de la soltería, que, claro, parece que cuando eres un hombre y estás soltero, es una soltería elegida, en plan, estoy soltero porque quiero, y si eres un ligón, a sobre eres el puto amo, pero cuando eres una chica y estás soltera, ya es porque nadie te quiere, nunca es soltera por voluntad propia, siempre la idea es estar soltera porque alguien tiene algún defecto y no la quieren, y si encima eres una ligona, estás desesperada. | CO7: 1. Reproduction | CP7: Direct Translation | CQ7: YES | CR7: SAME
A8: [empieza tema de conversación] | B8: Clar, però alhora és que vull dir, perdó, però ja no vull pas obrir una bandera lila, però a vegades com a tia és impossible fer-ho bé. Perquè si estàs soltera i no lligues, per a alguns ets d'autovalor, però per a alguns, quin és el teu fallo? Per què no estàs follant? En canvi, si estàs soltera i lligues molt, ets una guarra. Què faig? Mira, jo lo que trobo que hem de fer és lo que mos surti del xotxo, del cony, saps? | C8: Totalment. | D8: Clar, però alhora és que vull dir, perdó, però ja no vull pas obrir una bandera lila, però a vegades com a tia és impossible fer-ho bé. Perquè si estàs soltera i no lligues, per a alguns ets d'autovalor, però per a alguns, quin és el teu fallo? Per què no estàs follant? En canvi, si estàs soltera i lligues molt, ets una guarra. Què faig? Mira, jo lo que trobo que hem de fer és lo que mos surti del xotxo, del cony, saps? | E8: 4. Register and Tone | F8: 4.1 | G8: Hyperbole and exaggeration | H8: Mira, a ver, quiero decir, perdona, pero no quiero empezar una discusión, pero a veces, como mujer, es imposible hacerlo bien. Porque si estás soltera y no tienes pareja, para algunos tienes una autoestima altísima, pero para otros, ¿cuál es tu problema? ¿Por qué no tienes novio? En cambio, si estás soltera y tienes muchas citas, eres una aprovechada. ¿Qué hago? Mira, yo creo que lo que tenemos que hacer es lo que nos salga del corazón, lo que nos apetezca, ¿sabes? | I8: 4. Creative Shifts | J8: Abstraction – Paraphrase | K8: NO | N8: Claro, pero a la vez, quiero decir, perdón, pero no quiero abrir un debate feminista, pero a veces, como mujer, es imposible hacerlo bien. Porque si estás soltera y no ligas, para algunos tienes baja autoestima, pero para otros, ¿cuál es tu problema? ¿Por qué no estás teniendo relaciones? En cambio, si estás soltera y ligas mucho, eres una guarra. ¿Qué hago? Mira, yo creo que tenemos que hacer lo que nos salga de las pelotas, lo que nos dé la gana, ¿sabes? | O8: 4. Creative Shifts | P8: Abstraction – Paraphrase | Q8: YES | R8: LESS | T8: Claro, pero a la vez, quiero decir, perdona, pero ya no quiero abrir una "bandera lila", pero a veces, como mujer, es imposible hacerlo bien. Porque si estás soltera y no ligas, para algunos tienes baja autoestima, pero para otros, ¿cuál es tu problema? ¿Por qué no estás "liando"? En cambio, si estás soltera y ligas mucho, eres una "guarra". ¿Qué hago? Mira, yo creo que lo que tenemos que hacer es lo que nos salga de las pelotas, lo que nos plazca, ¿sabes? | U8: 4. Creative Shifts | V8: Abstraction – Paraphrase | W8: YES | X8: LESS | Z8: Claro, pero a la vez, quiero decir, disculpa, pero no quiero abrir un debate sobre esto, pero a veces, como mujer, es imposible hacerlo bien. Porque si estás soltera y no tienes pareja, para algunos eres una persona con baja autoestima, pero para otros, ¿cuál es tu problema? ¿Por qué no tienes novio? En cambio, si estás soltera y tienes muchas citas, eres una aprovechada. ¿Qué hago? Mira, yo creo que debemos hacer lo que nos salga del corazón, lo que nos apetezca, ¿sabes? | AA8: 4. Creative Shifts | AB8: Abstraction – Paraphrase | AC8: NO | AF8: Mira, claro, pero a la vez, a ver, perdón, pero no quiero precisamente levantar una polvareda, pero a veces, como mujer, es imposible hacerlo bien. Porque si estás soltera y no tienes pareja, para algunos eres de "autovalor", pero para otros, ¿cuál es tu problema? ¿Por qué no tienes novio? En cambio, si estás soltera y tienes muchas citas, eres una "guarra". ¿Qué hago? Mira, yo creo que lo que tenemos que hacer es lo que nos salga del corazón, del estómago, ¿sabes? | AG8: 3. Errors | AI8: NO | AL8: Clar, pero a la vez es que quiero decir, perdón, pero ya no quiero pas abrir una bandera lila, pero a veces como tía es imposible hacerlo bien. Porque si estás soltera y no estás liada, para algunos eres de autovalor, pero para otros, ¿cuál es tu fallo? ¿Por qué no estás follando? En cambio, si estás soltera y estás liada mucho, eres una guarra. ¿Qué hago? Mira, yo lo que encuentro que debemos hacer es lo que nos salga del churro, del cony, ¿sabes? | AM8: 3. Errors | AO8: NO | AR8: Claro, pero a la vez quiero decir, perdón, pero ya no quiero pasarlo a una bandera lila, pero a veces como tía es imposible hacerlo bien. Porque si estás soltera y no estás liada, para algunos eres de autovalor, pero para otros, ¿cuál es tu fallo? ¿Por qué no estás follando? En cambio, si estás soltera y estás liada mucho, eres una guarra. ¿Qué hago? Mira, lo que yo encuentro que debemos hacer es lo que nos salga del coño, del chocho, ¿sabes? | AS8: 1. Reproduction | AT8: Direct Translation | AU8: YES | AV8: SAME | AX8: Claro, pero a la vez es que quiero decir, perdón, pero ya no quiero pasar por una bandera lila, pero a veces, como tía, es imposible hacerlo bien. Porque si estás soltera y no estás liada, para algunos eres de autovalor, pero para otros, ¿cuál es tu fallo? ¿Por qué no estás follando? Por el contrario, si estás soltera y estás liada mucho, eres una guarra. ¿Qué hago? Mira, yo lo que encuentro que debemos hacer es lo que nos salga del churro, del cony, ¿sabes? | AY8: 3. Errors | BA8: NO | BD8: Claro, pero a la vez quiero decir, perdón, pero ya no quiero abrir una bandera lila, pero a veces, como mujer, es imposible hacerlo bien. Porque si estás soltera y no estás ligando, para algunos eres de autovalor, pero para otros, ¿cuál es tu fallo? ¿Por qué no estás follando? Por otro lado, si estás soltera y ligas mucho, eres una guarra. ¿Qué hago? Mira, lo que yo encuentro que debemos hacer es lo que nos salga del churro, del cony, ¿sabes? | BE8: 3. Errors | BG8: NO | BJ8: Claro, pero a la vez quiero decir, perdón, pero ya no quiero abrir una bandera lila, pero a veces, como tía, es imposible hacerlo bien. Porque si estás soltera y no estás ligando, para algunos eres de autovalor, pero para otros, ¿cuál es tu fallo? ¿Por qué no estás follando? En cambio, si estás soltera y ligas mucho, eres una guarra. ¿Qué hago? Mira, yo lo que encuentro que debemos hacer es lo que nos salga del churro, del cony, ¿sabes? | BK8: 3. Errors | BM8: NO | BP8: Claro, pero al mismo tiempo es que quiero decir, perdón, pero ya no quiero abrir una bandera lila, pero a veces como tía es imposible hacerlo bien. Porque si estás soltera y no ligas, para algunos eres de autovalor, pero para algunos, ¿cuál es tu fallo? ¿Por qué no follas? En cambio, si estás soltera y ligas mucho, eres una guarra. ¿Qué hago? Mira, lo que creo que debemos hacer es lo que nos salga de los cojones, del coño, ¿sabes? | BQ8: 4. Creative Shifts | BR8: Modification – Cultural | BS8: YES | BT8: SAME | BV8: Claro, pero a la vez quiero decir, perdona, pero ya no quiero abrir una bandera lila, pero a veces como tía es imposible hacerlo bien. Porque si estás soltera y no ligas, para algunos eres de autovalor, pero para algunos, ¿cuál es tu fallo? ¿Por qué no follas? En cambio, si estás soltera y ligas mucho, eres una guarra. ¿Qué hago? Mira, lo que creo que debemos hacer es lo que nos salga de los cojones, del coño, ¿sabes?" | BW8: 4. Creative Shifts | BX8: Modification – Cultural | BY8: YES | BZ8: SAME | CB8: Claro, pero a la vez es que quiero decir, perdón, pero ya no quiero abrir una bandera lila, pero a veces como tía es imposible hacerlo bien. Porque si estás soltera y no ligas, para algunos eres de autovalor, pero para algunos, ¿cuál es tu fallo? ¿Por qué no estás follando? En cambio, si estás soltera y atas mucho, eres una guarra. ¿Qué hago? Mira, yo lo que creo que tenemos que hacer es lo que nos salga del chocho, del coño, ¿sabes? | CC8: 1. Reproduction | CD8: Direct Translation | CE8: YES | CF8: SAME | CH8: Claro, pero al mismo tiempo es que quiero decir, perdón, pero ya no quiero abrir una bandera lila, pero a veces como tía es imposible hacerlo bien. Porque si estás soltera y no ligas, para algunos eres de autovalor, pero para algunos, ¿cuál es tu fallo? ¿Por qué no follas? En cambio, si estás soltera y ligas mucho, eres una guarra. ¿Qué hago? Mira, lo que creo que debemos hacer es lo que nos salga de los cojones, del coño, ¿sabes? | CI8: 4. Creative Shifts | CJ8: Modification – Cultural | CK8: YES | CL8: SAME | CN8: Claro, pero al mismo tiempo es que quiero decir, perdona, pero ya no quiero abrir una bandera lila, pero a veces como tía es imposible hacerlo bien. Porque si estás soltera y no ligas, para algunos eres de autovalor, pero para algunos, ¿cuál es tu fallo? ¿Por qué no follas? En cambio, si estás soltera y ligas mucho, eres una guarra. ¿Qué hago? Mira, lo que creo que debemos hacer es lo que nos salga de los cojones, del coño, ¿sabes? | CO8: 4. Creative Shifts | CP8: Modification – Cultural | CQ8: YES | CR8: SAME
A9: [empieza tema de conversación] | B9: Mira, jo, és a dir, jo realment me'n recordo etapes de la meva vida que estava soltera, que era una soltera infeliç, pel que dèiem de tot el rato estar pendent de dir, bueno, vale, molt bé, tinc amigues i família, però A veure quan ve el puto nòvio, saps? | C9: I com vius amb aquella impaciència, i també allò de no saber-ho si estàs fent bé, rotllo, si lligava, em sentia una guarra per lligar, i si no lligava pensava, per què ningú m'està tirant la canya? | D9: Mira, jo, és a dir, jo realment me'n recordo etapes de la meva vida que estava soltera, que era una soltera infeliç, pel que dèiem de tot el rato estar pendent de dir, bueno, vale, molt bé, tinc amigues i família, però A veure quan ve el puto nòvio, saps? | E9: 1. Lexicon and Vocabulary | F9: 1.1 | G9: Lexicon of insult | H9: Mira, yo, es decir, yo realmente recuerdo etapas de mi vida en las que estaba soltera, y era una soltera infeliz, por eso siempre estaba pendiente de pensar, bueno, vale, tengo amigas y familia, pero... a ver, ¿cuándo aparece el puto novio, sabes? | I9: 1. Reproduction | J9: Direct Translation | K9: YES | L9: SAME | N9: Mira, yo, o sea, yo realmente recuerdo etapas de mi vida en las que estaba soltera, y era una soltera infeliz, como decíamos, siempre pendiente de pensar: bueno, vale, tengo amigas y familia, pero a ver, ¿cuándo aparece el puto novio?, ¿sabes? | O9: 1. Reproduction | P9: Direct Translation | Q9: YES | R9: SAME | T9: Mira, yo, o sea, yo realmente recuerdo etapas de mi vida en las que estaba soltera, y era una soltera infeliz, como decíamos, siempre pendiente de pensar: bueno, vale, tengo amigas y familia, pero, a ver, ¿cuándo aparece el puto novio?, ¿sabes? | U9: 1. Reproduction | V9: Direct Translation | W9: YES | X9: SAME | Z9: Mira, yo, o sea, yo realmente recuerdo etapas de mi vida en las que estaba soltera, y era una soltera infeliz, por lo que siempre estaba pendiente de pensar: bueno, vale, tengo amigas y familia, pero... a ver, ¿cuándo aparece el condenado novio, sabes? | AA9: 4. Creative Shifts | AB9: Abstraction – Superordinate Term | AC9: NO | AF9: Mira, yo, es decir, yo realmente recuerdo etapas de mi vida en las que estaba soltera, y era una soltera infeliz, porque, como decíamos constantemente, estaba pendiente de pensar: "Vale, bien, tengo amigas y familia, pero... ¿cuándo aparecerá el condenado novio, sabes?". | AG9: 4. Creative Shifts | AH9: Abstraction – Superordinate Term | AI9: NO | AL9: Mira, yo, es decir, yo realmente me acuerdo de etapas de mi vida en las que estaba soltera, que era una soltera infeliz, y de todo el rato estar pendiente de decir, bueno, vale, muy bien, tengo amigas y familia, pero a ver cuándo llega el puto novio, ¿sabes? | AM9: 1. Reproduction | AN9: Direct Translation | AO9: YES | AP9: SAME | AR9: Mira, yo, es decir, yo realmente me acuerdo de etapas de mi vida en las que estaba soltera, que era una soltera infeliz, de lo que siempre decíamos de estar pendientes de decir, bueno, vale, muy bien, tengo amigas y familia, pero a ver cuando llega el puto novio, ¿sabes? | AS9: 1. Reproduction | AT9: Direct Translation | AU9: YES | AV9: SAME | AX9: Mira, yo, es decir, yo realmente me acuerdo de etapas de mi vida en las que estaba soltera, que era una soltera infeliz, y de lo que siempre decíamos, bueno, vale, muy bien, tengo amigas y familia, pero a ver cuando llega el puto novio, ¿sabes? | AY9: 1. Reproduction | AZ9: Direct Translation | BA9: YES | BB9: SAME | BD9: Mira, yo, quiero decir, realmente me acuerdo de etapas de mi vida en las que estaba soltera, que era una soltera infeliz, porque siempre estábamos pendientes de decir, bueno, vale, muy bien, tengo amigas y familia, pero ¿cuándo llega ese maldito novio, sabes? | BE9: 4. Creative Shifts | BF9: Abstraction – Superordinate Term | BG9: NO | BJ9: Mira, yo, es decir, yo realmente me acuerdo de etapas de mi vida en las que estaba soltera, que era una soltera infeliz, y siempre decíamos que estábamos pendientes de decir, bueno, vale, muy bien, tengo amigas y familia, pero a ver cuándo llega ese puto novio, ¿sabes? | BK9: 1. Reproduction | BL9: Direct Translation | BM9: YES | BN9: SAME | BP9: Mira, yo, es decir, yo realmente me acuerdo etapas de mi vida que estaba soltera, que era una soltera infeliz, por lo que decíamos de todo el rato estar pendiente de decir, bueno, vale, muy bien, tengo amigas y familia, pero A ver cuando viene el puto novio, ¿sabes? | BQ9: 1. Reproduction | BR9: Direct Translation | BS9: YES | BT9: SAME | BV9: Oye, mira, yo, o sea, yo realmente recuerdo etapas de mi vida que estaba soltera, que era una soltera infeliz, por lo que decíamos todo el rato de "bueno, vale, muy bien, tengo amigas y familia", pero ¿a ver cuándo viene el put* novio?, sabes? | BW9: 1. Reproduction | BX9: Direct Translation | BY9: YES | BZ9: SAME | CB9: Oye, mira, yo, o sea, yo realmente recuerdo etapas de mi vida que estaba soltera, que era una soltera infeliz, por lo que decíamos todo el rato de "bueno, vale, muy bien, tengo amigas y familia", pero ¿a ver cuándo viene el puto novio?, sabes? | CC9: 1. Reproduction | CD9: Direct Translation | CE9: YES | CF9: SAME | CH9: Mira, yo, es decir, yo realmente me acuerdo etapas de mi vida que estaba soltera, que era una soltera infeliz, por lo que decíamos de todo el rato estar pendiente de decir, bueno, vale, muy bien, tengo amigas y familia, pero A ver cuándo viene el puto novio, ¿sabes? | CI9: 1. Reproduction | CJ9: Direct Translation | CK9: YES | CL9: SAME | CN9: Mira, yo, es decir, yo realmente me acuerdo etapas de mi vida que estaba soltera, que era una soltera infeliz, por lo que decíamos de todo el rato estar pendiente de decir, bueno, vale, muy bien, tengo amigas y familia, pero A ver cuándo viene el puto novio, ¿sabes? | CO9: 1. Reproduction | CP9: Direct Translation | CQ9: YES | CR9: SAME
