Workbook
Name CreativeShifts: Lists!$E$1:$E$7
Name Errors: Lists!$D$1:$D$1
Name Omissions: Lists!$C$1:$C$2
Name Reproduction: Lists!$B$1:$B$4

Sheet Lists
A1: 1. Reproduction | B1: Retention | C1: Creative Omission | D1: Error | E1: Abstraction – Superordinate Term | G1: 1. Reproduction | H1: Reproduction
A2: 2. Omissions | B2: Specification | C2: Shortcut Solution | E2: Abstraction – Paraphrase | G2: 2. Omissions | H2: Omissions
A3: 3. Errors | B3: Direct Translation | E3: Concretisation – Addition | G3: 3. Errors | H3: Errors
A4: 4. Creative Shifts | B4: Official Translation | E4: Concretisation – Completion | G4: 4. Creative Shifts | H4: CreativeShifts
E5: Modification – Cultural
E6: Modification – Situational
E7: Modification – Historical

Sheet Dashboard
B1: EVALUATION DASHBOARD — Category Distribution (4 Models × 5 Prompts)
B3: ℹ Fill dropdowns in the Evaluation sheet — counts update here automatically.
B5: Model A
B6: Prompt | C6: Reproduction | D6: Omissions | E6: Errors | F6: Creative Shifts | G6: Total | H6: % Done
B7: Baseline | C7: =COUNTIF(Evaluation!K3:K202,"1. Reproduction") -> 38 | D7: =COUNTIF(Evaluation!K3:K202,"2. Omissions") -> 10 | E7: =COUNTIF(Evaluation!K3:K202,"3. Errors") -> 16 | F7: =COUNTIF(Evaluation!K3:K202,"4. Creative Shifts") -> 129 | G7: =COUNTIF(Evaluation!K3:K202,"<>") -> 193 | H7: =IFERROR(G7/200,"") -> 0.965
B8: Few-shot 1 | C8: =COUNTIF(Evaluation!Q3:Q202,"1. Reproduction") -> 46 | D8: =COUNTIF(Evaluation!Q3:Q202,"2. Omissions") -> 8 | E8: =COUNTIF(Evaluation!Q3:Q202,"3. Errors") -> 15 | F8: =COUNTIF(Evaluation!Q3:Q202,"4. Creative Shifts") -> 124 | G8: =COUNTIF(Evaluation!Q3:Q202,"<>") -> 193 | H8: =IFERROR(G8/200,"") -> 0.965
B9: Few-shot 2 | C9: =COUNTIF(Evaluation!W3:W202,"1. Reproduction") -> 46 | D9: =COUNTIF(Evaluation!W3:W202,"2. Omissions") -> 12 | E9: =COUNTIF(Evaluation!W3:W202,"3. Errors") -> 13 | F9: =COUNTIF(Evaluation!W3:W202,"4. Creative Shifts") -> 122 | G9: =COUNTIF(Evaluation!W3:W202,"<>") -> 193 | H9: =IFERROR(G9/200,"") -> 0.965
B10: CoT 1 | C10: =COUNTIF(Evaluation!AC3:AC202,"1. Reproduction") -> 42 | D10: =COUNTIF(Evaluation!AC3:AC202,"2. Omissions") -> 11 | E10: =COUNTIF(Evaluation!AC3:AC202,"3. Errors") -> 12 | F10: =COUNTIF(Evaluation!AC3:AC202,"4. Creative Shifts") -> 128 | G10: =COUNTIF(Evaluation!AC3:AC202,"<>") -> 193 | H10: =IFERROR(G10/200,"") -> 0.965
B11: CoT 2 | C11: =COUNTIF(Evaluation!AI3:AI202,"1. Reproduction") -> 41 | D11: =COUNTIF(Evaluation!AI3:AI202,"2. Omissions") -> 13 | E11: =COUNTIF(Evaluation!AI3:AI202,"3. Errors") -> 14 | F11: =COUNTIF(Evaluation!AI3:AI202,"4. Creative Shifts") -> 125 | G11: =COUNTIF(Evaluation!AI3:AI202,"<>") -> 193 | H11: =IFERROR(G11/200,"") -> 0.965
B14: Model B
B15: Prompt | C15: Reproduction | D15: Omissions | E15: Errors | F15: Creative Shifts | G15: Total | H15: % Done
B16: Baseline | C16: =COUNTIF(Evaluation!AO3:AO202,"1. Reproduction") -> 77 | D16: =COUNTIF(Evaluation!AO3:AO202,"2. Omissions") -> 3 | E16: =COUNTIF(Evaluation!AO3:AO202,"3. Errors") -> 21 | F16: =COUNTIF(Evaluation!AO3:AO202,"4. Creative Shifts") -> 92 | G16: =COUNTIF(Evaluation!AO3:AO202,"<>") -> 193 | H16: =IFERROR(G16/200,"") -> 0.965
B17: Few-shot 1 | C17: =COUNTIF(Evaluation!AU3:AU202,"1. Reproduction") -> 76 | D17: =COUNTIF(Evaluation!AU3:AU202,"2. Omissions") -> 3 | E17: =COUNTIF(Evaluation!AU3:AU202,"3. Errors") -> 17 | F17: =COUNTIF(Evaluation!AU3:AU202,"4. Creative Shifts") -> 97 | G17: =COUNTIF(Evaluation!AU3:AU202,"<>") -> 193 | H17: =IFERROR(G17/200,"") -> 0.965
B18: Few-shot 2 | C18: =COUNTIF(Evaluation!BA3:BA202,"1. Reproduction") -> 76 | D18: =COUNTIF(Evaluation!BA3:BA202,"2. Omissions") -> 6 | E18: =COUNTIF(Evaluation!BA3:BA202,"3. Errors") -> 17 | F18: =COUNTIF(Evaluation!BA3:BA202,"4. Creative Shifts") -> 94 | G18: =COUNTIF(Evaluation!BA3:BA202,"<>") -> 193 | H18: =IFERROR(G18/200,"") -> 0.965
B19: CoT 1 | C19: =COUNTIF(Evaluation!BG3:BG202,"1. Reproduction") -> 82 | D19: =COUNTIF(Evaluation!BG3:BG202,"2. Omissions") -> 2 | E19: =COUNTIF(Evaluation!BG3:BG202,"3. Errors") -> 18 | F19: =COUNTIF(Evaluation!BG3:BG202,"4. Creative Shifts") -> 91 | G19: =COUNTIF(Evaluation!BG3:BG202,"<>") -> 193 | H19: =IFERROR(G19/200,"") -> 0.965
B20: CoT 2 | C20: =COUNTIF(Evaluation!BM3:BM202,"1. Reproduction") -> 79 | D20: =COUNTIF(Evaluation!BM3:BM202,"2. Omissions") -> 2 | E20: =COUNTIF(Evaluation!BM3:BM202,"3. Errors") -> 20 | F20: =COUNTIF(Evaluation!BM3:BM202,"4. Creative Shifts") -> 92 | G20: =COUNTIF(Evaluation!BM3:BM202,"<>") -> 193 | H20: =IFERROR(G20/200,"") -> 0.965
B23: Model C
B24: Prompt | C24: Reproduction | D24: Omissions | E24: Errors | F24: Creative Shifts | G24: Total | H24: % Done
B25: Baseline | C25: =COUNTIF(Evaluation!BS3:BS202,"1. Reproduction") -> 95 | D25: =COUNTIF(Evaluation!BS3:BS202,"2. Omissions") -> 4 | E25: =COUNTIF(Evaluation!BS3:BS202,"3. Errors") -> 12 | F25: =COUNTIF(Evaluation!BS3:BS202,"4. Creative Shifts") -> 82 | G25: =COUNTIF(Evaluation!BS3:BS202,"<>") -> 193 | H25: =IFERROR(G25/200,"") -> 0.965
B26: Few-shot 1 | C26: =COUNTIF(Evaluation!BY3:BY202,"1. Reproduction") -> 82 | D26: =COUNTIF(Evaluation!BY3:BY202,"2. Omissions") -> 9 | E26: =COUNTIF(Evaluation!BY3:BY202,"3. Errors") -> 12 | F26: =COUNTIF(Evaluation!BY3:BY202,"4. Creative Shifts") -> 90 | G26: =COUNTIF(Evaluation!BY3:BY202,"<>") -> 193 | H26: =IFERROR(G26/200,"") -> 0.965
B27: Few-shot 2 | C27: =COUNTIF(Evaluation!CE3:CE202,"1. Reproduction") -> 95 | D27: =COUNTIF(Evaluation!CE3:CE202,"2. Omissions") -> 2 | E27: =COUNTIF(Evaluation!CE3:CE202,"3. Errors") -> 8 | F27: =COUNTIF(Evaluation!CE3:CE202,"4. Creative Shifts") -> 88 | G27: =COUNTIF(Evaluation!CE3:CE202,"<>") -> 193 | H27: =IFERROR(G27/200,"") -> 0.965
B28: CoT 1 | C28: =COUNTIF(Evaluation!CK3:CK202,"1. Reproduction") -> 93 | D28: =COUNTIF(Evaluation!CK3:CK202,"2. Omissions") -> 4 | E28: =COUNTIF(Evaluation!CK3:CK202,"3. Errors") -> 11 | F28: =COUNTIF(Evaluation!CK3:CK202,"4. Creative Shifts") -> 85 | G28: =COUNTIF(Evaluation!CK3:CK202,"<>") -> 193 | H28: =IFERROR(G28/200,"") -> 0.965
B29: CoT 2 | C29: =COUNTIF(Evaluation!CQ3:CQ202,"1. Reproduction") -> 93 | D29: =COUNTIF(Evaluation!CQ3:CQ202,"2. Omissions") -> 4 | E29: =COUNTIF(Evaluation!CQ3:CQ202,"3. Errors") -> 9 | F29: =COUNTIF(Evaluation!CQ3:CQ202,"4. Creative Shifts") -> 87 | G29: =COUNTIF(Evaluation!CQ3:CQ202,"<>") -> 193 | H29: =IFERROR(G29/200,"") -> 0.965
B32: Model D
B33: Prompt | C33: Reproduction | D33: Omissions | E33: Errors | F33: Creative Shifts | G33: Total | H33: % Done
B34: Baseline | C34: =COUNTIF(Evaluation!#REF!,"1. Reproduction") -> #REF! | D34: =COUNTIF(Evaluation!#REF!,"2. Omissions") -> #REF! | E34: =COUNTIF(Evaluation!#REF!,"3. Errors") -> #REF! | F34: =COUNTIF(Evaluation!#REF!,"4. Creative Shifts") -> #REF! | G34: =COUNTIF(Evaluation!#REF!,"<>") -> #REF! | H34: =IFERROR(G34/200,"")
B35: Few-shot 1 | C35: =COUNTIF(Evaluation!#REF!,"1. Reproduction") -> #REF! | D35: =COUNTIF(Evaluation!#REF!,"2. Omissions") -> #REF! | E35: =COUNTIF(Evaluation!#REF!,"3. Errors") -> #REF! | F35: =COUNTIF(Evaluation!#REF!,"4. Creative Shifts") -> #REF! | G35: =COUNTIF(Evaluation!#REF!,"<>") -> #REF! | H35: =IFERROR(G35/200,"")
B36: Few-shot 2 | C36: =COUNTIF(Evaluation!#REF!,"1. Reproduction") -> #REF! | D36: =COUNTIF(Evaluation!#REF!,"2. Omissions") -> #REF! | E36: =COUNTIF(Evaluation!#REF!,"3. Errors") -> #REF! | F36: =COUNTIF(Evaluation!#REF!,"4. Creative Shifts") -> #REF! | G36: =COUNTIF(Evaluation!#REF!,"<>") -> #REF! | H36: =IFERROR(G36/200,"")
B37: CoT 1 | C37: =COUNTIF(Evaluation!#REF!,"1. Reproduction") -> #REF! | D37: =COUNTIF(Evaluation!#REF!,"2. Omissions") -> #REF! | E37: =COUNTIF(Evaluation!#REF!,"3. Errors") -> #REF! | F37: =COUNTIF(Evaluation!#REF!,"4. Creative Shifts") -> #REF! | G37: =COUNTIF(Evaluation!#REF!,"<>") -> #REF! | H37: =IFERROR(G37/200,"")
B38: CoT 2 | C38: =COUNTIF(Evaluation!#REF!,"1. Reproduction") -> #REF! | D38: =COUNTIF(Evaluation!#REF!,"2. Omissions") -> #REF! | E38: =COUNTIF(Evaluation!#REF!,"3. Errors") -> #REF! | F38: =COUNTIF(Evaluation!#REF!,"4. Creative Shifts") -> #REF! | G38: =COUNTIF(Evaluation!#REF!,"<>") -> #REF! | H38: =IFERROR(G38/200,"")

Sheet Evaluation
J1: Model A - TranslateGemma | AN1: Model B - Qwen | BR1: Model C - Salamandra
A2: text_previous | B2: text_analyzed | C2: text_after | D2: text_analyzed | E2: macrocategory | F2: subcategory_num | G2: subcategory | H2: Definition or Translation | I2: Referencia | J2: translation_translategemma_baseline | K2: Baseline ▼ Category | L2: Baseline ▼ Subcategory | M2: Mantains informal register? | N2: Intensity of informality | O2: Baseline Comments | P2: translation_translategemma_fewshot1 | Q2: Few-shot 1 ▼ Category | R2: Few-shot 1 ▼ Subcategory | S2: Mantains informal register? | U2: Few-shot 1 Comments | V2: translation_translategemma_fewshot2 | W2: Few-shot 2 ▼ Category | X2: Few-shot 2 ▼ Subcategory | Y2: Mantains informal register? | Z2: Intensity of informality | AA2: Few-shot 2 Comments | AB2: translation_translategemma_CoT1 | AC2: CoT 1 ▼ Category | AD2: CoT 1 ▼ Subcategory | AE2: Mantains informal register? | AF2: Intensity of informality | AG2: CoT 1 Comments | AH2: translation_translategemma_CoT2 | AI2: CoT 2 ▼ Category | AJ2: CoT 2 ▼ Subcategory | AK2: Mantains informal register? | AL2: Intensity of informality | AM2: CoT 2 Comments | AN2: translation_qwen_baseline | AO2: Baseline ▼ Category | AP2: Baseline ▼ Subcategory | AQ2: Mantains informal register? | AR2: Intensity of informality | AS2: Baseline Comments | AT2: translation_qwen_fewshot1 | AU2: Few-shot 1 ▼ Category | AV2: Few-shot 1 ▼ Subcategory | AW2: Mantains informal register? | AX2: Intensity of informality | AY2: Few-shot 1 Comments | AZ2: translation_qwen_fewshot2 | BA2: Few-shot 2 ▼ Category | BB2: Few-shot 2 ▼ Subcategory | BC2: Mantains informal register? | BD2: Intensity of informality | BE2: Few-shot 2 Comments | BF2: translation_qwen_CoT1 | BG2: CoT 1 ▼ Category | BH2: CoT 1 ▼ Subcategory | BI2: Mantains informal register? | BJ2: Intensity of informality | BK2: CoT 1 Comments | BL2: translation_qwen_CoT2 | BM2: CoT 2 ▼ Category | BN2: CoT 2 ▼ Subcategory | BO2: Mantains informal register? | BP2: Intensity of informality | BQ2: CoT 2 Comments | BR2: translation_salam_baseline | BS2: Baseline ▼ Category | BT2: Baseline ▼ Subcategory | BU2: Mantains informal register? | BV2: Intensity of informality | BW2: Baseline Comments | BX2: translation_salam_fewshot1 | BY2: Few-shot 1 | BZ2: Few-shot 1 ▼ Subcategory | CA2: Mantains informal register? | CB2: Intensity of informality | CC2: Few-shot 1 Comments | CD2: translation_salam_fewshot2 | CE2: Few-shot 2 ▼ Category | CF2: Few-shot 2 ▼ Subcategory | CG2: Mantains informal register? | CH2: Intensity of informality | CI2: Few-shot 2 Comments | CJ2: translation_salam_CoT1 | CK2: CoT 1 ▼ Category | CL2: CoT 1 ▼ Subcategory | CM2: Mantains informal register? | CN2: Intensity of informality | CO2: CoT 1 Comments | CP2: translation_salam_CoT2 | CQ2: CoT 2 ▼ Category | CR2: CoT 2 ▼ Subcategory | CS2: Mantains informal register? | CT2: Intensity of informality | CU2: CoT 2 Comments
A3: [empieza tema de conversación] | B3: Hay sitios que va todo el mundo y yo de verdad que quiero saber los entresijos de los personajacos que deben de ir al MediaMarkt. | C3: Es que esto tiene que ser maravilloso porque te puedes encontrar de to. De una idea, nos lo va a contar el invitado de hoy. | D3: Hay sitios que va todo el mundo y yo de verdad que quiero saber los entresijos de los personajacos que deben de ir al MediaMarkt. | E3: 1. Lexicon and Vocabulary | F3: 1.2 | G3: Colloquial lexicon and slang | J3: There are places that everyone goes to, and I'm genuinely curious to know the details about the types of people who visit MediaMarkt. | K3: 4. Creative Shifts | L3: Abstraction – Superordinate Term | M3: NO | O3: Cambridge / WordReference | P3: There are places that everyone goes to, and I'm genuinely curious to know all the details about the characters who are supposed to be going to MediaMarkt. | Q3: 4. Creative Shifts | R3: Abstraction – Superordinate Term | S3: NO | U3: Cambridge / WordReference | V3: There are places that everyone goes to, and I'm genuinely curious about the inner workings of the people who must go to MediaMarkt. | W3: 4. Creative Shifts | X3: Abstraction – Superordinate Term | Y3: NO | AB3: There are places that everyone goes to, and I'm genuinely curious about the details of the people who must go to MediaMarkt. | AC3: 4. Creative Shifts | AD3: Abstraction – Superordinate Term | AE3: NO | AH3: There are places that everyone goes to, and I really want to know the ins and outs of the people who are supposed to be going to MediaMarkt. | AI3: 4. Creative Shifts | AJ3: Abstraction – Superordinate Term | AK3: NO | AN3: There are places that everyone goes to, and I really want to know the behind-the-scenes stuff about these little characters who should be going to MediaMarkt. | AO3: 4. Creative Shifts | AP3: Abstraction – Superordinate Term | AQ3: NO | AS3: Cambridge / WordReference | AT3: There are places everyone goes to, and I really want to know the ins and outs of those little characters who must go to MediaMarkt. | AU3: 4. Creative Shifts | AV3: Abstraction – Superordinate Term | AW3: NO | AY3: Cambridge / WordReference | AZ3: There are places everyone goes, and I really want to know the inside stories of those characters who must go to MediaMarkt. | BA3: 4. Creative Shifts | BB3: Abstraction – Superordinate Term | BC3: YES | BE3: Cambridge / WordReference | BF3: "There are places that everyone goes to, and I really want to know the inside stories of those little characters who must go to MediaMarkt." | BG3: 4. Creative Shifts | BH3: Modification – Situational | BI3: NO | BK3: Cambridge / WordReference | BL3: There are shows that everyone watches, and I really want to know the behind-the-scenes stuff about those characters that air on MediaMarkt. | BM3: 4. Creative Shifts | BN3: Abstraction – Superordinate Term | BO3: YES | BQ3: Cambridge / WordReference | BR3: There are places that everyone goes and I really want to know the ins and outs of the characters who must go to MediaMarkt. | BS3: 4. Creative Shifts | BT3: Abstraction – Superordinate Term | BU3: NO | BW3: Cambridge / WordReference | BX3: There are places that everyone goes and I really want to know the ins and outs of the characters who must go to MediaMarkt. | BY3: 4. Creative Shifts | BZ3: Abstraction – Superordinate Term | CA3: NO | CC3: Cambridge / WordReference | CD3: There are places that everyone goes and I really want to know the ins and outs of the character types who must go to the MediaMarkt. | CE3: 4. Creative Shifts | CF3: Abstraction – Superordinate Term | CG3: NO | CI3: Cambridge / WordReference | CJ3: There are places that everyone goes and I really want to know the ins and outs of the characters who must go to MediaMarkt. | CK3: 4. Creative Shifts | CL3: Abstraction – Superordinate Term | CM3: NO | CO3: Cambridge / WordReference | CP3: There are places that everyone goes and I really want to know the ins and outs of the character types who must go to MediaMarkt | CQ3: 4. Creative Shifts | CR3: Abstraction – Superordinate Term | CS3: NO | CU3: Cambridge / WordReference
A4: [empieza tema de conversación] | B4: Gente que te intenta regatear, se cree que si se lleva 2 portátiles, se lo voy a, se le va a bajar el precio. Efectivamente, ni que yo fuera el dueño de allí de la tienda. Hermano, si yo me llevo estos 2 portátiles, ¿en cuánto me lo dejas? | C4: Efectivamente, ni que yo fuera el dueño de allí de la tienda. Hermano, si yo me llevo estos 2 portátiles, ¿en cuánto me lo dejas? Pues al mismo precio. | D4: Gente que te intenta regatear, se cree que si se lleva 2 portátiles, se lo voy a, se le va a bajar el precio. Efectivamente, ni que yo fuera el dueño de allí de la tienda. Hermano, si yo me llevo estos 2 portátiles, ¿en cuánto me lo dejas? | E4: 3. Pragmatics and Discourse | F4: 3.2 | G4: Familiar address or vocatives | H4: Brother | I4: WordReference | J4: People try to haggle with you, thinking that if they buy two laptops, they'll get a discount. It's as if they think I'm the owner of the shop. Listen, if I buy these two laptops, what price will you give them to me for? | K4: 4. Creative Shifts | L4: Modification – Situational | M4: NO | P4: People try to haggle with you, thinking that if they buy two laptops, I'll, or they'll, get a lower price. As if I'm the owner of the shop. Mate, if I buy these two laptops, how much will you let me have them for? | Q4: 4. Creative Shifts | R4: Modification – Cultural | S4: YES | U4: WordReference | V4: People who try to haggle with you, they think that if they buy two laptops, I'm going to give them a discount. As if I own the shop! Mate, if I buy these two laptops, how much will you let me have them for? | W4: 4. Creative Shifts | X4: Modification – Cultural | Y4: YES | AA4: WordReference | AB4: People try to haggle with you, thinking that if they buy two laptops, I'm going to, or they're going to, get a discount. It's as if I own the shop. Mate, if I buy these two laptops, how much will you let me have them for? | AC4: 4. Creative Shifts | AD4: Modification – Cultural | AE4: YES | AG4: WordReference | AH4: People try to haggle with you, thinking that if they buy two laptops, I'll give them a discount. As if I own the shop! Mate, if I buy these two laptops, how much will you let me have them for? | AI4: 4. Creative Shifts | AJ4: Modification – Cultural | AK4: YES | AM4: WordReference | AN4: People who try to haggle with you, thinking that if they take two laptops, I'll give them a discount. Yeah, like I was the owner of the store. Bro, if I take these two laptops, how much would you charge me? Well, at the same price. | AO4: 4. Creative Shifts | AP4: Modification – Cultural | AQ4: YES | AS4: WordReference | AT4: Sure, like he thinks if he takes two laptops, I'm gonna give them to him, he's gonna get a discount. Yeah, like I was the owner of that store. Bro, if I take these two laptops, how much would you charge me? Well, the same price. | AU4: 4. Creative Shifts | AV4: Modification – Cultural | AW4: YES | AY4: WordReference | AZ4: Bro, people who try to haggle with you, thinking that if they take two laptops, I'm gonna give them a deal, like the price will drop. Yeah, like I was the owner of that store. Bro, if I take these two laptops, how much are you gonna charge me? Well, the same price. | BA4: 4. Creative Shifts | BB4: Modification – Situational | BC4: YES | BF4: People who try to haggle with you, thinking that if they take two laptops, I'll give them a better price. Indeed, as if I were the owner of the store. Bro, if I take these two laptops, how much would you charge me? Well, the same price. | BG4: 4. Creative Shifts | BH4: Concretisation – Addition | BI4: YES | BL4: People who try to haggle with you, thinking that if you take two laptops, I'm going to, they're going to lower the price. Yeah, as if I were the owner of that store. Bro, if I take these two laptops, how much will you let me have them for? | BM4: 4. Creative Shifts | BN4: Modification – Cultural | BO4: YES | BR4: People who try to haggle with you, they think that if they take 2 laptops, the price will go down. Indeed, as if I were the owner of the store. Brother, if I take these 2 laptops, how much do you leave me? | BS4: 1. Reproduction | BT4: Direct Translation | BU4: YES | BW4: Wordreference | BX4: People who try to haggle with you, they think that if he takes two laptops, then his price will go down. Well actually, like I own this store. Brother, if I take these two laptops, how much do you leave them? | BY4: 1. Reproduction | BZ4: Direct Translation | CA4: YES | CC4: WordReference | CD4: People who try to haggle, they think that if they take 2 laptops, the price will go down. Effectively, as if I were the owner of the store. Brother, if I take these 2 laptops, how much do you leave me? | CE4: 1. Reproduction | CF4: Direct Translation | CG4: YES | CI4: WordReference | CJ4: People who try to haggle with you, they think that if they take 2 laptops, the price will go down. Indeed, as if I were the owner of the store. Brother, if I take these 2 laptops, how much do you leave me? | CK4: 1. Reproduction | CL4: Direct Translation | CM4: YES | CO4: WordReference | CP4: People who try to haggle with you, they think that if they take 2 laptops, the price will go down. Indeed, as if I were the owner of the store. Brother, if I take these 2 laptops, what price do you leave me? Indeed, at the same price. | CQ4: 1. Reproduction | CR4: Direct Translation | CS4: YES | CU4: WordReference
A5: [empieza tema de conversación] | B5: Esta vez, una de mis regiones favoritas, la región del fish and chips, de la peña con los dientes de aquella manera, de esa gente que todo el mundo habla en su idioma, pero ellos no hablan en el idioma de nadie. Vamos a conocer cómo es Inglaterra. | C5: Vamos a conocer cómo es Inglaterra. | D5: Esta vez, una de mis regiones favoritas, la región del fish and chips, de la peña con los dientes de aquella manera, de esa gente que todo el mundo habla en su idioma, pero ellos no hablan en el idioma de nadie. Vamos a conocer cómo es Inglaterra. | E5: 1. Lexicon and Vocabulary | F5: 1.2 | G5: Colloquial lexicon and slang | H5: Folks | I5: WordReference | J5: This time, we're visiting one of my favourite regions, the land of fish and chips, of those people with that distinctive look, those folks that everyone talks about in their own language, but who don't speak anyone else's language. Let's find out what England is really like. | K5: 4. Creative Shifts | L5: Abstraction – Superordinate Term | M5: NO | P5: This time, we're heading to one of my favourite regions: the land of fish and chips, the place with all those people with funny teeth, that crowd everyone talks about, who speak in their own language, but don't speak anyone else's. Let's find out what England is really like. | Q5: 4. Creative Shifts | R5: Abstraction – Superordinate Term | S5: NO | V5: This time, we're going to one of my favourite regions, the land of fish and chips, of those people with the distinctive teeth, of those folks that everyone talks about in their own language, but who don't speak anyone else's language. Let's find out what England is really like. | W5: 4. Creative Shifts | X5: Abstraction – Superordinate Term | Y5: NO | AB5: "This time, we're going to one of my favourite regions – the land of fish and chips, of those people with that distinctive way of speaking, that group who everyone talks about in their own language, but who don't speak anyone else's language. Let's find out what England is really like. | AC5: 4. Creative Shifts | AD5: Abstraction – Superordinate Term | AE5: NO | AH5: "This time, we're heading to one of my favourite regions – the land of fish and chips, the place with those distinctive teeth, that group of people everyone talks about in their own language, but who don't speak anyone else's language. Let's find out what England is really like." | AI5: 3. Errors | AK5: NO | AN5: This time, one of my favorite regions, the fish and chips region, the group with those teeth in that way, the people everyone talks about in their own language, but they don't speak anyone else's language. Let's find out what England is like. | AO5: 4. Creative Shifts | AP5: Abstraction – Superordinate Term | AQ5: NO | AT5: This time, one of my favorite regions, the fish and chips region, the area with those teeth-like things, the people who everyone talks about in their own language, but they don't speak anyone else's language. Let's find out what England is like. | AU5: 3. Errors | AW5: NO | AZ5: This time, one of my favorite regions, the fish and chips region, the area with those teeth-like things, the people who everyone talks about in their own language, but they don’t speak anyone else’s language. Let’s find out what England is like. | BA5: 3. Errors | BC5: NO | BF5: This time, one of my favorite regions, the fish and chips region, the area with those teeth in that way, the people everyone talks about in their own language, but they don't speak anyone else's language. Let's find out what England is like. | BG5: 3. Errors | BI5: NO | BL5: This time, one of my favorite regions, the fish and chips region, the group with those teeth in that way, that bunch of people everyone talks about in their own language, but they don’t speak anyone else’s language. Let’s find out what England is like. | BM5: 4. Creative Shifts | BN5: Abstraction – Superordinate Term | BO5: NO | BR5: This time, one of my favorite regions, the region of fish and chips, of the people with teeth like that, of that people who everyone talks about in their language, but they don't talk in the language of no one. Let's get to know England. | BS5: 4. Creative Shifts | BT5: Abstraction – Superordinate Term | BU5: NO | BX5: This time, one of my favorite regions, the region of fish and chips, people with teeth like that, those people who everyone talks about their own language, but they don’t speak anyone’s language. Let’s go see how England is." | BY5: 4. Creative Shifts | BZ5: Abstraction – Superordinate Term | CA5: NO | CD5: This time, one of my favorite regions, the fish and chips region, of the people with teeth like that, of that people that everyone talks about in their language, but they don't speak in the language of no one. Let's get to know England. | CE5: 4. Creative Shifts | CF5: Abstraction – Superordinate Term | CG5: NO | CJ5: This time, one of my favorite regions, the region of fish and chips, of the person with teeth like that, of that people who everyone talks about in their language, but they don't speak in the language of no one. Let's get to know England. | CK5: 4. Creative Shifts | CL5: Abstraction – Superordinate Term | CM5: NO | CP5: This time, one of my favorite regions, the region of fish and chips, of the person with teeth like that, of that people who everyone talks about in their language, but they don't speak in the language of no one. Let's get to know England. | CQ5: 4. Creative Shifts | CR5: Abstraction – Superordinate Term | CS5: NO
A6: [empieza tema de conversación] | B6: Tío, ¿quién te enseñó español para hablar tan bien? | C6: Hice una carrera de Estudios Hispánicos, por eso hablo español. Aparte de eso, siempre estaba con mis amigos españoles. O sea, estando en Japón, de entre 4 a 7 hablaban en español y era el único japonés en ese grupo hispanohablante. | D6: Tío, ¿quién te enseñó español para hablar tan bien? | E6: 3. Pragmatics and Discourse | F6: 3.2 | G6: Familiar address or vocatives | H6: brother / mate / buddy / pal / dude / bro / man | I6: WordReference | J6: "Mate, who taught you Spanish so you could speak it so well?" | K6: 4. Creative Shifts | L6: Modification – Cultural | M6: YES | P6: "Mate, who taught you Spanish so you could speak it so well?" | Q6: 4. Creative Shifts | R6: Modification – Cultural | S6: YES | V6: "Mate, who taught you Spanish so you could speak it so well?" | W6: 4. Creative Shifts | X6: Modification – Cultural | Y6: YES | AB6: "Mate, who taught you Spanish so you could speak it so well?" | AC6: 4. Creative Shifts | AD6: Modification – Cultural | AE6: YES | AH6: "Mate, who taught you Spanish so you could speak it so well?" | AI6: 4. Creative Shifts | AJ6: Modification – Cultural | AK6: YES | AN6: Uncle, who taught you Spanish to speak so well? | AO6: 1. Reproduction | AP6: Direct Translation | AQ6: NO | AT6: Bro, who taught you Spanish to speak so well? | AU6: 4. Creative Shifts | AV6: Modification – Cultural | AW6: YES | AZ6: Bro, who taught you Spanish to speak so well? | BA6: 4. Creative Shifts | BB6: Modification – Cultural | BC6: YES | BF6: Uncle, who taught you Spanish to speak so well? | BG6: 1. Reproduction | BH6: Direct Translation | BI6: NO | BL6: Dude, who taught you Spanish to speak so well? | BM6: 4. Creative Shifts | BN6: Modification – Cultural | BO6: YES | BR6: Dude, who taught you Spanish to speak so well? | BS6: 4. Creative Shifts | BT6: Modification – Cultural | BU6: YES | BX6: Oui, who taught you how to speak Spanish so well? | BY6: 3. Errors | CA6: NO | CD6: Bro, who taught you Spanish to speak so well? | CE6: 4. Creative Shifts | CF6: Modification – Cultural | CG6: YES | CJ6: Dude, who taught you Spanish to speak so well? | CK6: 4. Creative Shifts | CL6: Modification – Cultural | CM6: YES | CP6: Dude, who taught you Spanish to speak so well? | CQ6: 4. Creative Shifts | CR6: Modification – Cultural | CS6: YES
A7: [empieza tema de conversación] | B7: ¿La música española te gusta? Sí, Canto del Loco, Amaral, La Oreja de Van Gogh. Esto es muy fuerte, tío. | C7: Me encanta. Amaral me parece la mejor artista de España. | D7: ¿La música española te gusta? Sí, Canto del Loco, Amaral, La Oreja de Van Gogh. Esto es muy fuerte, tío. | E7: 3. Pragmatics and Discourse | F7: 3.2 | G7: Familiar address or vocatives | H7: brother / mate / buddy / pal / dude / bro / man | I7: WordReference | J7: Do you like Spanish music? Yes, Canto del Loco, Amaral, La Oreja de Van Gogh. This is really good, mate. | K7: 4. Creative Shifts | L7: Modification – Cultural | M7: YES | P7: Do you like Spanish music? Yeah, Canto del Loco, Amaral, La Oreja de Van Gogh. This is really good, mate. | Q7: 4. Creative Shifts | R7: Modification – Cultural | S7: YES | V7: "Do you like Spanish music? Yeah, Canto del Loco, Amaral, La Oreja de Van Gogh. This is really good, man." | W7: 4. Creative Shifts | X7: Modification – Cultural | Y7: YES | AB7: Do you like Spanish music? Yes, Canto del Loco, Amaral, La Oreja de Van Gogh. This is really good, mate. | AC7: 4. Creative Shifts | AD7: Modification – Cultural | AE7: YES | AH7: Do you like Spanish music? Yeah, Canto del Loco, Amaral, La Oreja de Van Gogh. This is really good, mate. | AI7: 4. Creative Shifts | AJ7: Modification – Cultural | AK7: YES | AN7: Do you like Spanish music? Yeah, Canto del Loco, Amaral, La Oreja de Van Gogh. That's really strong, dude. | AO7: 4. Creative Shifts | AP7: Modification – Cultural | AQ7: YES | AT7: Do you like Spanish music? Yeah, Canto del Loco, Amaral, La Oreja de Van Gogh. That's really strong, dude. | AU7: 4. Creative Shifts | AV7: Modification – Cultural | AW7: YES | AZ7: Do you like Spanish music? Yeah, Canto del Loco, Amaral, La Oreja de Van Gogh. That's really strong, man. | BA7: 4. Creative Shifts | BB7: Modification – Cultural | BC7: YES | BF7: Do you like Spanish music? Yeah, Canto del Loco, Amaral, La Oreja de Van Gogh. That's really strong, dude. | BG7: 4. Creative Shifts | BH7: Modification – Cultural | BI7: YES | BL7: "Do you like Spanish music? Yeah, Canto del Loco, Amaral, La Oreja de Van Gogh. This is really strong, dude." | BM7: 4. Creative Shifts | BN7: Modification – Cultural | BO7: YES | BR7: Do you like Spanish music? Yes, Canto del Loco, Amaral, La Oreja de Van Gogh. This is very strong, dude. | BS7: 4. Creative Shifts | BT7: Modification – Cultural | BU7: YES | BX7: "The Spanish music do you like? Yes, ""Canto del Loco"", ""Amaral"", ""La Oreja de Van Gogh""." This is very strong, man. | BY7: 4. Creative Shifts | BZ7: Modification – Cultural | CA7: YES | CD7: Do you like Spanish music? Yes, Canto del Loco, Amaral, La Oreja de Van Gogh. This is very strong, dude. | CE7: 4. Creative Shifts | CF7: Modification – Cultural | CG7: YES | CJ7: Do you like Spanish music? Yes, Canto del Loco, Amaral, La Oreja de Van Gogh. This is very strong, dude. | CK7: 4. Creative Shifts | CL7: Modification – Cultural | CM7: YES | CP7: Do you like Spanish music? Yes, Canto del Loco, Amaral, La Oreja de Van Gogh. This is very strong, dude. | CQ7: 4. Creative Shifts | CR7: Modification – Cultural | CS7: YES
A8: [empieza tema de conversación] | B8: Como una persona que eres japonés: ¿no te parece como un poco raro que prácticamente todo el mundo esté que no caga con Japón? | C8: Sí, la verdad es que sí. Todo el mundo está metido en el tema de animes y viene aquí comprando figuras y todo eso. A mí me parece bien, pero que es raro. | D8: Como una persona que eres japonés: ¿no te parece como un poco raro que prácticamente todo el mundo esté que no caga con Japón? | E8: 1. Lexicon and Vocabulary | F8: 1.4 | G8: Idiomatic expressions and colloquial phraseology | H8: To be hyped / Over the moon | J8: "As a Japanese person, don't you think it's a bit strange that practically everyone seems to have a negative opinion of Japan?" | K8: 3. Errors | M8: NO | P8: As a person who is Japanese, don't you think it's a bit weird that practically everyone is so obsessed with Japan? | Q8: 4. Creative Shifts | R8: Abstraction – Paraphrase | S8: NO | V8: As someone who's Japanese, doesn't it seem a bit odd that almost everyone is so obsessed with Japan? | W8: 4. Creative Shifts | X8: Abstraction – Paraphrase | Y8: NO | AB8: As a Japanese person, doesn't it seem a bit strange to you that practically everyone is so keen on Japan? | AC8: 4. Creative Shifts | AD8: Abstraction – Paraphrase | AE8: NO | AH8: As someone who is Japanese, don't you think it's a bit strange that practically everyone is so obsessed with Japan? | AI8: 4. Creative Shifts | AJ8: Abstraction – Paraphrase | AK8: NO | AN8: As someone who's Japanese: don't you think it's kind of weird that practically everyone is obsessed with Japan? | AO8: 4. Creative Shifts | AP8: Abstraction – Paraphrase | AQ8: NO | AT8: As a person who's Japanese: Doesn't it seem a little weird that practically everyone's all over Japan these days? | AU8: 3. Errors | AW8: NO | AZ8: As someone who's Japanese: Doesn't it seem a bit weird that practically everyone's obsessed with Japan? | BA8: 4. Creative Shifts | BB8: Abstraction – Paraphrase | BC8: NO | BF8: As a person who is Japanese: doesn't it seem a bit weird that practically everyone is into Japan these days? | BG8: 4. Creative Shifts | BH8: Abstraction – Paraphrase | BI8: NO | BL8: As a Japanese person, don’t you think it’s kind of weird that practically everyone is all over Japan these days? | BM8: 3. Errors | BO8: NO | BR8: As a person who is Japanese: don't you think it's a bit weird that practically everyone is obsessed with Japan? | BS8: 4. Creative Shifts | BT8: Abstraction – Paraphrase | BU8: NO | BX8: As a person who is Japanese: Doesn’t it seem like kind of weird that practically everyone seems obsessed with Japan?"} | BY8: 4. Creative Shifts | BZ8: Abstraction – Paraphrase | CA8: NO | CD8: As a Japanese person: Don't you think it's a bit weird that practically everyone is obsessed with Japan? | CE8: 4. Creative Shifts | CF8: Abstraction – Paraphrase | CG8: NO | CJ8: As a person who is Japanese: don't you think it's a bit strange that practically everyone is obsessed with Japan? | CK8: 4. Creative Shifts | CL8: Abstraction – Paraphrase | CM8: NO | CP8: As a person who is Japanese: Don't you think it's a bit strange that practically everyone is obsessed with Japan? | CQ8: 4. Creative Shifts | CR8: Abstraction – Paraphrase | CS8: NO
A9: [empieza tema de conversación] | B9: Yo trabajaba en un edificio, en una multinacional. Lanzan un comunicado, una agencia de todos súper pijos y todos súper moneymakers y aquí somos todos la hostia, pues había un zurullo, tío, un zurullo fuera del váter. | C9: Eso se hizo viral y todo el mundo, claro, al final los conocemos todos, aunque estéis en agencias diferentes, todo el mundo empezó a hacerse eco, salió hasta en Twitter... | D9: Yo trabajaba en un edificio, en una multinacional. Lanzan un comunicado, una agencia de todos superpijos y todos súper moneymakers y aquí somos todos la hostia, pues había un zurullo, tío, un zurullo fuera del váter. | E9: 1. Lexicon and Vocabulary | F9: 1.3 | G9: Lexical shortening and abbreviations | J9: I used to work in a building, at a multinational company. They put out a statement – a really posh agency, full of people obsessed with making money, and they acted like they were the best. But there was this incident, you know, something happened outside the toilet. | K9: 2. Omissions | L9: Shortcut Solution | M9: NO | P9: So, I used to work in a building, at a multinational company. They put out a statement – this agency was full of posh people, all making loads of money, and we were all supposed to be the best. But then, there was this incident, mate, a real mess. It happened outside the toilet. | Q9: 4. Creative Shifts | R9: Abstraction – Superordinate Term | S9: NO | V9: "I used to work in a building, at a multinational company. They put out a statement – it was an agency full of really posh people, all about making money, and we were all supposed to be the best. But there was this... incident, mate, this thing happened outside the toilet. | W9: 4. Creative Shifts | X9: Abstraction – Superordinate Term | Y9: NO | AB9: "I worked in a building, at a multinational company. They put out a statement – it was an agency full of really posh people, all obsessed with making money, and we were all supposed to be the best. But there was this... incident, you know, a mess outside the toilet." | AC9: 4. Creative Shifts | AD9: Abstraction – Superordinate Term | AE9: NO | AH9: "I used to work in a building, at a multinational company. They put out a statement – this agency was full of really posh people, all obsessed with making money, and we were all supposed to be the best. But then, there was this incident, you know, something happened outside the toilet. | AI9: 4. Creative Shifts | AJ9: Modification – Situational | AK9: NO | AN9: I used to work in a building, at a multinational company. They released a statement, through an agency full of super posh people and all these super money-makers, and here we were all just the worst, man, there was a total mess, like, a complete disaster outside the bathroom. | AO9: 1. Reproduction | AP9: Direct Translation | AQ9: YES | AT9: I used to work in a building, at a multinational company. They released a statement, through an agency full of super posh people and all these super money-makers, and here we were, everyone was totally messed up, there was this guy, dude, a total loser, like, outside the bathroom. | AU9: 1. Reproduction | AV9: Direct Translation | AW9: YES | AZ9: I used to work in a building, in a multinational company. They released a statement, through an agency full of super posh people and all these super money-makers, and here we were, everyone was totally messed up, because there was this guy, man, a total mess-up, outside the toilet. | BA9: 1. Reproduction | BB9: Direct Translation | BC9: YES | BF9: I used to work in a building, at a multinational company. They released a statement, through an agency full of super posh people and all these super money-makers, and here we were all the talk, because there was this guy, man, a real loser, outside the restroom. | BG9: 1. Reproduction | BH9: Direct Translation | BI9: YES | BL9: I used to work in a building, in a multinational. They released a statement, an agency full of all super posh people and all super money-makers, and here we were all the worst, because there was a total idiot, dude, an idiot outside the toilet. | BM9: 1. Reproduction | BN9: Direct Translation | BO9: YES | BR9: I used to work in an office, in a multinational company. They send out a press release, a super posh PR agency and everyone's super money-makers and we're all so cool, there was a turd, dude, a turd outside the toilet. | BS9: 1. Reproduction | BT9: Direct Translation | BU9: YES | BX9: I worked in a building at a multinational company. They issued a statement, all their employees were very posh and they were all making money, and here we are all like hell, there was a turd outside the toilet. | BY9: 1. Reproduction | BZ9: Direct Translation | CA9: YES | CD9: I used to work in a building, in a multinational company. They send out a statement, a super posh agency and all the super moneymakers and here we are all amazing, well there was a turd, dude, a turd outside the toilet. | CE9: 1. Reproduction | CF9: Direct Translation | CG9: YES | CJ9: I used to work in a building, in a multinational. They send out a statement, a super posh agency and all the super money makers and here we are all the hype, there was a turd, dude, a turd outside the toilet. | CK9: 1. Reproduction | CL9: Direct Translation | CM9: YES | CP9: I used to work in a building, in a multinational. They send out a statement, a super posh agency and all the super moneymakers and here we are all the hype, there was a turd, dude, a turd outside the toilet. | CQ9: 1. Reproduction | CR9: Direct Translation | CS9: YES
A10: [empieza tema de conversación] | B10: Yo voy a abrir un melón. En tus vídeos se critica mucho a los franceses. Yo hoy vengo a defenderles, tío. Son los menos tocahuevos. | C10: De verdad, te lo juro, o sea, llegan, te piden su café latte y ya está, y no te dan por culo Pero es que tengo 3 nacionalidades, les metí a un patadón, tengo top 3 Empezando por abajo, los chinos son unos maleducados Y yo les volví a decir Pero bueno, por lo menos nos han pedido en mi cara que te agradece Eso está bien, eh Luego los segundos, bueno, es que están ahí los portugueses y los italianos | D10: Yo voy a abrir un melón. En tus vídeos se critica mucho a los franceses. Yo hoy vengo a defenderles, tío. Son los menos tocahuevos. | E10: 1. Lexicon and Vocabulary | F10: 1.2 | G10: Colloquial lexicon and slang | H10: Pain in the ass / butt | I10: Cambridge | J10: Okay, I'm going to open a melon. In your videos, you criticise the French a lot. But today, I'm here to defend them, mate. They're the least intrusive. | K10: 3. Errors | M10: NO | P10: I'm going to open up about something. In your videos, you criticise the French a lot. Today, I'm here to defend them, mate. They're the least annoying. | Q10: 4. Creative Shifts | R10: Abstraction – Superordinate Term | S10: NO | V10: "I'm going to cut open a melon. In your videos, you criticize the French a lot. I'm here today to defend them, mate. They're the least intrusive. | W10: 3. Errors | Y10: NO | AB10: "I'm going to cut open a melon. In your videos, you criticise the French a lot. But today, I'm here to defend them, mate. They're the least intrusive." | AC10: 3. Errors | AE10: NO | AH10: I'm going to open a melon. In your videos, you criticise the French a lot. I'm here today to defend them, mate. They're the least nosy. | AI10: 3. Errors | AK10: NO | AN10: I'm going to open a watermelon. In your videos, the French are criticized a lot. I'm here today to defend them, man. They're the least of the touchy-feely types. | AO10: 3. Errors | AQ10: NO | AT10: I'm gonna open up a watermelon. In your videos, you criticize the French a lot. I'm here today to defend them, dude. They're the least of the touchy-feely types. | AU10: 3. Errors | AW10: NO | AZ10: I'm gonna cut open a watermelon. In your videos, the French are criticized a lot. Today I'm here to defend them, man. They're the least of the annoying ones. | BA10: 4. Creative Shifts | BB10: Abstraction – Superordinate Term | BC10: NO | BF10: "I'm gonna open a watermelon. In your videos, the French are criticized a lot. Today I'm here to defend them, dude. They're the least of the tocahuevos." | BG10: 1. Reproduction | BH10: Retention | BI10: NO | BL10: I'm going to open a watermelon. In your videos, the French are criticized a lot. I'm here today to defend them, dude. They're the least annoying ones. | BM10: 4. Creative Shifts | BN10: Abstraction – Superordinate Term | BO10: NO | BR10: I am going to open a melon. In your videos, French people are criticized a lot. Today I come to defend them, dude. They are the least annoying. | BS10: 4. Creative Shifts | BT10: Abstraction – Superordinate Term | BU10: NO | BX10: I am going to open a melon. In your videos they criticize France a lot. Today I come to defend them, man. They are the least annoying | BY10: 4. Creative Shifts | BZ10: Abstraction – Superordinate Term | CA10: NO | CD10: I am going to open a melon. In your videos, the French are criticized a lot. Today I come to defend them, dude. They are the least annoying. | CE10: 4. Creative Shifts | CF10: Abstraction – Superordinate Term | CG10: NO | CJ10: I am going to open a melon. In your videos, French people are criticized a lot. Today I come to defend them, dude. They are the least touchy-feely. | CK10: 3. Errors | CM10: NO | CP10: I'm going to open a can of worms. In your videos, you criticize the French a lot. Today I'm here to defend them, man. They're the least annoying. | CQ10: 4. Creative Shifts | CR10: Abstraction – Superordinate Term | CS10: NO
A11: [empieza tema de conversación] | B11: Era por la mañana, pero te estoy hablando 7 y media. Vemos entrar a una chica y a un chico jovencitos. Se pusieron ahí enfrente de la barra y empezaron a magrearse, a darse unos buenos besitos y nosotras diciendo, bueno, pues bien. | C11: Limpiando un vaso, sí. Y se estaban comiendo, literal. Se levanta el chico y se va al baño. 30 segundos, se levanta la chica y se va para el baño. Pasa media hora, me da por preguntarle a mi compañera, oye, ¿tú has visto salir a estos 2 de la tienda? Porque no había nadie, yo salgo al baño de los chicos Pone el código y estaban ahí Pasándoselo súper bien | D11: Era por la mañana, pero te estoy hablando 7 y media. Vemos entrar a una chica y a un chico jovencitos. Se pusieron ahí enfrente de la barra y empezaron a magrearse, a darse unos buenos besitos y nosotras diciendo, bueno, pues bien. | E11: 1. Lexicon and Vocabulary | F11: 1.2 | G11: Colloquial lexicon and slang | H11: To grope / Make out | I11: WordReference | J11: It was in the morning, but I'm telling you this at 7:30. We saw a young girl and a young guy walk in. They went and sat at the bar and started getting all affectionate, giving each other proper kisses, and we were just thinking, "Okay, fine." | K11: 4. Creative Shifts | L11: Abstraction – Paraphrase | M11: NO | P11: It was in the morning, but I'm telling you this at 7:30. We saw a young girl and a young guy walk in. They went and stood in front of the bar and started getting all lovey-dovey, giving each other proper kisses, and we were just like, "Okay, good for them." | Q11: 4. Creative Shifts | R11: Abstraction – Paraphrase | S11: NO | V11: It was in the morning, but I'm telling you this at 7:30. We saw a young girl and a young guy walk in. They went to the bar and started getting all lovey-dovey, giving each other proper kisses, and we were just like, "Okay, whatever." | W11: 4. Creative Shifts | X11: Abstraction – Paraphrase | Y11: NO | AB11: It was in the morning, but I'm telling you this at 7:30. We saw a young girl and a young boy walk in. They went and sat at the bar and started getting all affectionate, giving each other proper kisses, and we were just thinking, "Okay, fine." | AC11: 4. Creative Shifts | AD11: Abstraction – Paraphrase | AE11: NO | AH11: It was in the morning, but I'm telling you this at 7:30. We saw a young girl and a young guy walk in. They went and sat at the bar and started getting all cosy, giving each other proper kisses, and we were just thinking, "Okay, fine." | AI11: 4. Creative Shifts | AJ11: Abstraction – Paraphrase | AK11: NO | AN11: It was in the morning, but I'm talking to you at 7:30. We saw a young guy and girl walk in. They stood right in front of the bar and started getting all affectionate, giving each other some big kisses, and us saying, "Well, that's nice." | AO11: 4. Creative Shifts | AP11: Abstraction – Paraphrase | AQ11: NO | AT11: It was morning, but I'm talking to you at 7:30. We saw a girl and a young guy walking in. They stood right in front of the bar and started getting all affectionate, giving each other some big kisses, and us saying, "Well, okay, that's fine." | AU11: 4. Creative Shifts | AV11: Abstraction – Paraphrase | AW11: NO | AZ11: It was morning, but I'm talking to you at 7:30. We see a girl and a young guy walking in. They stood right in front of the bar and started getting all affectionate, giving each other nice kisses, and us saying, "Well, okay, that's fine." | BA11: 4. Creative Shifts | BB11: Abstraction – Paraphrase | BC11: NO | BF11: It was in the morning, but I'm talking to you at 7:30. We saw a young girl and a young guy walk in. They stood right in front of the bar and started making out, giving each other some good kisses, and us saying, "Well, that's nice." | BG11: 1. Reproduction | BH11: Direct Translation | BI11: YES | BL11: It was morning, but I’m talking to you at 7:30. We saw a girl and a young guy walk in. They stood right in front of the bar and started flirting, giving each other some nice kisses, and we were saying, well, okay, that’s fine. | BM11: 4. Creative Shifts | BN11: Abstraction – Paraphrase | BO11: NO | BR11: It was morning, but I'm talking to you at 7:30. We see a girl and a young boy enter. They stood there in front of the bar and started groping each other, giving each other big kisses, and we were saying, well, that's good. | BS11: 1. Reproduction | BT11: Direct Translation | BU11: YES | BX11: It was morning, but I am talking to you at seven thirty. We see a girl and a young guy enter. They stood there facing the bar and started groping each other, giving themselves good kisses and we saying, well, okay | BY11: 1. Reproduction | BZ11: Direct Translation | CA11: YES | CD11: It was in the morning, but I'm talking to you at 7:30. We see a girl and a young boy enter. They stood there in front of the bar and started to caress each other, giving each other good kisses and we were saying, well, that's good. | CE11: 4. Creative Shifts | CF11: Abstraction – Paraphrase | CG11: NO | CJ11: It was in the morning, but I'm talking to you at 7:30. We see a girl and a young boy enter. They stood there in front of the bar and started to caress each other, giving each other good kisses and we were saying, well, that's good. | CK11: 4. Creative Shifts | CL11: Abstraction – Paraphrase | CM11: NO | CP11: It was in the morning, but I'm talking to you at 7:30. We see a girl and a young boy enter. They stood there in front of the bar and started touching each other, giving each other big kisses, and we were saying, well, that's good. | CQ11: 4. Creative Shifts | CR11: Abstraction – Paraphrase | CS11: NO
A12: [empieza tema de conversación] | B12: Entonces fui, miraba los pisos, era a lo mejor como un bajo a tomar por el culo con humedades 1 habitación asquerosa. Mil euros cada uno. Conseguí llorarle un montón a los de la residencia. Puede que haya un sitio, pero tienes que compartir con 5 israelíes. Me doy con un canto en los dientes. | C12: Yo no sabía que Jerusalén iba a hacer un frío que te cagas. No tenía edredón y me pasé, no sé si te digo, a lo mejor los 6 meses durmiendo en el saco de dormir hasta que no me compré una almohada. | D12: Entonces fui, miraba los pisos, era a lo mejor como un bajo a tomar por el culo con humedades 1 habitación asquerosa. Mil euros cada uno. Conseguí llorarle un montón a los de la residencia. Puede que haya un sitio, pero tienes que compartir con 5 israelíes. Me doy con un canto en los dientes. | E12: 1. Lexicon and Vocabulary | F12: 1.4 | G12: Idiomatic expressions and colloquial phraseology | H12: count your lucky stars / count your blessings / consider yourself lucky | I12: WordReference | J12: So, I went to look at some flats, and they were all awful – basically, damp, cramped one-bedroom places. And they were charging a thousand euros each. I managed to get the people at the student accommodation to feel sorry for me. There might be a place available, but you'd have to share with five Israelis. I'm just grateful to have somewhere to stay. | K12: 4. Creative Shifts | L12: Abstraction – Paraphrase | M12: NO | P12: So, I went there, looking at the flats. They were, at best, tiny studios, probably damp, with one disgusting room. And they were charging a thousand euros each. I managed to get on the good side of the people at the residence, so hopefully, there might be a place, but you'd have to share with five Israelis. Still, I'm happy enough. | Q12: 3. Errors | S12: NO | V12: So, I went there, looking at the apartments, and it was probably like a tiny, damp basement, one disgusting room. A thousand euros each. I managed to get on their good side, really pull at their heartstrings. There might be a place, but you have to share with five Israelis. I'm happy just to have somewhere. | W12: 4. Creative Shifts | X12: Abstraction – Paraphrase | Y12: NO | AB12: "So, I went to look at the apartments, and they were, well, maybe like a ground-floor flat, damp, with one disgusting room. And they were asking a thousand euros each. I managed to really plead with the people at the residence. There might be a place, but you'd have to share with five Israelis. I'm just glad to have somewhere. | AC12: 4. Creative Shifts | AD12: Abstraction – Paraphrase | AE12: NO | AH12: So, I went to look at the apartments, and they were awful – basically, damp, one-bedroom dumps. And they were charging a thousand euros each. I managed to get the people at the residence to lower the price a bit. There might be a place available, but you'd have to share with five Israelis. I'm just grateful to have somewhere. | AI12: 4. Creative Shifts | AJ12: Abstraction – Paraphrase | AK12: NO | AN12: So I went, I was looking at the apartments, it was maybe like a basement with dampness, one disgusting room. A thousand euros each. I managed to cry a lot to the housing office. There might be a place, but you have to share with five Israelis. I'm just biting my tongue. | AO12: 3. Errors | AQ12: NO | AT12: So I went, I was looking at the apartments, it was maybe like a basement to take a dump with dampness, one filthy room. Each one was a thousand euros. I begged the housing office so much, maybe there's a place, but you have to share with five Israelis. I'm just shaking my head in disbelief. | AU12: 3. Errors | AW12: NO | AZ12: Then I went, looking at the apartments—it was basically like a basement to take a dump with dampness, one disgusting room. Each one was a thousand euros. I cried a lot to the housing office. There might be a spot, but you have to share with five Israelis. I'm just glad I got it. | BA12: 4. Creative Shifts | BB12: Abstraction – Paraphrase | BC12: NO | BF12: So I went, I was looking at apartments—it was kind of like a basement with dampness, one disgusting room. Each one was a thousand euros. I cried a lot to the people at the housing office. There might be a place, but you have to share with five Israelis. I'm just laughing through my teeth. | BG12: 3. Errors | BI12: NO | BL12: So I went there, looking at the apartments — it was maybe like a basement that was a total mess, with dampness and just one filthy room. Each one cost a thousand euros. I really pleaded with the people at the housing office. There might be a place, but you have to share it with five Israelis. I’m going to end up laughing at myself. | BM12: 3. Errors | BO12: NO | BR12: So I went, I looked at the flats, it was maybe like a basement to take the piss with damp 1 disgusting room. A thousand euros each. I managed to cry a lot to the people at the residence. Maybe there's a place, but you have to share with 5 Israelis. I give myself a pat on the back. | BS12: 3. Errors | BU12: NO | BX12: So then I went there, looked at the flats - maybe like a basement somewhere with mould, one disgusting room, each one costs a thousand Euros. Managed to make them cry a lot at the hostel. Maybe there will be a place, but you have to share with five Israelis. I give myself credit. | BY12: 3. Errors | CA12: NO | CD12: Then I went, I looked at the flats, it was maybe like a basement to take the piss with damp 1 disgusting room. 1,000 euros each. I managed to cry a lot to the people at the residence. Maybe there's a place, but you have to share with 5 Israelis. I give myself a pat on the back. | CE12: 3. Errors | CG12: NO | CJ12: Then I went, I looked at the flats, it was maybe like a basement to take the piss with damp 1 disgusting room. A thousand euros each. I managed to cry a lot to the people at the residence. Maybe there's a place, but you have to share with 5 Israelis. I give myself a pat on the back | CK12: 3. Errors | CM12: NO | CP12: Then I went, I looked at the flats, it was maybe like a basement to take the piss with damp 1 disgusting room. A thousand euros each. I managed to cry a lot to the people at the residence. There may be a place, but you have to share with 5 Israelis. I give myself a pat on the back. | CQ12: 3. Errors | CS12: NO
